Workbook

Sheet SPB Loss Calculator
A1: Parametric Basic Loss Calculator for SPB / Modular Three-Phase Inverter | J1: Quick Summary
A2: Enter only the yellow cells. Output cells update by formula. Energy inputs are assumed in mJ per switching event at the reference voltage/current.
J3: Module Vdc | K3: =B24 -> 150 | L3: V | M3: Efficiency | N3: =F29 -> 99.066365
A4: System inputs | J4: Device V rating | K4: =B28 -> 225 | L4: V | M4: Total loss | N4: =F27 -> 2827.3003
A5: Total DC-link voltage | B5: 1200 | C5: V | D5: Total battery/DC-link voltage applied to series SPB stack | J5: Phase current | K5: =B26 -> 248.10764 | L5: Arms | M5: Cond. loss | N5: =F24 -> 147.73777
A6: Number of series SPB modules | B6: 8 | C6: - | D6: Number of cascaded three-phase bridge submodules | J6: Switches | K6: =B30 -> 48 | L6: - | M6: Sw. loss | N6: =F26 -> 2679.5625
A7: Output power | B7: 300 | C7: kW | D7: Mechanical/electrical output power used for inverter efficiency calculation | J7: Input DC current | K7: =B27 -> 250 | L7: A | M7: Module power | N7: =B31 -> 37.5
A8: Power factor | B8: 0.95 | C8: - | D8: Used to estimate phase current from P = √3·VLL,rms·I·pf | J8: Loss / module | K8: =F27/B6 -> 353.41254 | L8: W | M8: Loss / switch avg. | N8: =F27/B30 -> 58.90209
A9: Modulation index | B9: 1 | C9: - | D9: Sinusoidal PWM fundamental modulation index; 1.154 possible with zero-sequence extension
A10: Device voltage margin | B10: 1.5 | C10: pu | D10: Suggested device blocking rating = Vmodule × margin
A11: Device current margin | B11: 1.25 | C11: pu | D11: Suggested current rating = Irms × margin
A12: Device / switching inputs
A13: Eon per switch @ reference | B13: 0.1 | C13: mJ | D13: Turn-on energy of one device at Vref/Iref
A14: Eoff per switch @ reference | B14: 0.1 | C14: mJ | D14: Turn-off energy of one device at Vref/Iref
A15: Rds(on) per switch | B15: 5 | C15: mΩ | D15: On-state resistance of one switch at selected temperature
A16: Switching frequency | B16: 300 | C16: kHz | D16: PWM switching frequency per submodule
A17: Reference voltage for Eon/Eoff | B17: 200 | C17: V | D17: Datasheet/test voltage for switching energy
A18: Reference current for Eon/Eoff | B18: 100 | C18: A | D18: Datasheet/test current for switching energy
A19: Energy voltage exponent | B19: 1 | C19: - | D19: Use 1 for linear voltage scaling
A20: Energy current exponent | B20: 1 | C20: - | D20: Use 1 for linear current scaling
A21: Additional fixed losses | B21: 0 | C21: W | D21: Optional control/gate-drive/cooling/auxiliary losses
A23: Calculated ratings | E23: Loss results
A24: DC voltage per SPB module | B24: =B5/B6 -> 150 | C24: V | E24: Conduction loss total | F24: =B6*3*B26^2*(B14/1000) -> 147.73777 | G24: W
A25: Fundamental VLL,rms per module | B25: =0.6123724357*B9*B24 -> 91.855865 | C25: V | E25: Switching energy scaled | F25: =(B12+B13)*(B24/B17)^B19*(B26/B18)^B20 -> 0.18608073 | G25: mJ/event
A26: Estimated AC phase current per module | B26: =B7*1000/(SQRT(3)*B25*B8)/B6 -> 248.10764 | C26: Arms | E26: Switching loss total | F26: =B30*(F25/1000)*(B16*1000) -> 2679.5625 | G26: W
A27: DC input current, ideal | B27: =B7*1000/B5 -> 250 | C27: A | E27: Total inverter loss | F27: =F24+F26+B21 -> 2827.3003 | G27: W
A28: Suggested device blocking rating | B28: =B24*B10 -> 225 | C28: V | E28: Input power including losses | F28: =B7*1000+F27 -> 302827.3 | G28: W
A29: Suggested device current rating | B29: =B26*B11 -> 310.13455 | C29: A | E29: Efficiency | F29: =B7*1000/F28*100 -> 99.066365 | G29: %
A30: Total number of switches | B30: =6*B6 -> 48 | C30: - | E30: Loss share: conduction | F30: =IF(F27=0,0,F24/F27*100) -> 5.2254005 | G30: %
A31: Module output power | B31: =B7/B6 -> 37.5 | C31: kW | E31: Loss share: switching | F31: =IF(F27=0,0,F26/F27*100) -> 94.774599 | G31: %
A34: Switching frequency sweep
A35: fsw (kHz) | B35: Conduction loss (W) | C35: Switching loss (W) | D35: Total loss (W) | E35: Efficiency (%)
A36: =B16/20*2 -> 30 | B36: =$F$24 -> 147.73777 | C36: =$B$30*($F$25/1000)*(A36*1000) -> 267.95625 | D36: =B36+C36+$B$21 -> 415.69402 | E36: =$B$7*1000/($B$7*1000+D36)*100 -> 99.861627
A37: =B16/20*2*2 -> 60 | B37: =$F$24 -> 147.73777 | C37: =$B$30*($F$25/1000)*(A37*1000) -> 535.91251 | D37: =B37+C37+$B$21 -> 683.65027 | E37: =$B$7*1000/($B$7*1000+D37)*100 -> 99.772635
A38: =B16/20*3*2 -> 90 | B38: =$F$24 -> 147.73777 | C38: =$B$30*($F$25/1000)*(A38*1000) -> 803.86876 | D38: =B38+C38+$B$21 -> 951.60653 | E38: =$B$7*1000/($B$7*1000+D38)*100 -> 99.683801
A39: =B16/20*4*2 -> 120 | B39: =$F$24 -> 147.73777 | C39: =$B$30*($F$25/1000)*(A39*1000) -> 1071.825 | D39: =B39+C39+$B$21 -> 1219.5628 | E39: =$B$7*1000/($B$7*1000+D39)*100 -> 99.595125
A40: =B16/20*5*2 -> 150 | B40: =$F$24 -> 147.73777 | C40: =$B$30*($F$25/1000)*(A40*1000) -> 1339.7813 | D40: =B40+C40+$B$21 -> 1487.519 | E40: =$B$7*1000/($B$7*1000+D40)*100 -> 99.506607
A41: =B16/20*6*2 -> 180 | B41: =$F$24 -> 147.73777 | C41: =$B$30*($F$25/1000)*(A41*1000) -> 1607.7375 | D41: =B41+C41+$B$21 -> 1755.4753 | E41: =$B$7*1000/($B$7*1000+D41)*100 -> 99.418246
A42: =B16/20*7*2 -> 210 | B42: =$F$24 -> 147.73777 | C42: =$B$30*($F$25/1000)*(A42*1000) -> 1875.6938 | D42: =B42+C42+$B$21 -> 2023.4315 | E42: =$B$7*1000/($B$7*1000+D42)*100 -> 99.330042
A43: =B16/20*8*2 -> 240 | B43: =$F$24 -> 147.73777 | C43: =$B$30*($F$25/1000)*(A43*1000) -> 2143.65 | D43: =B43+C43+$B$21 -> 2291.3878 | E43: =$B$7*1000/($B$7*1000+D43)*100 -> 99.241994
...

Sheet Sensitivity
A1: Basic Sensitivity: Efficiency vs Switching Frequency
A3: fsw (kHz) | B3: 5 | C3: 10 | D3: 15 | E3: 20 | F3: 30 | G3: 50 | H3: 100
A4: Efficiency | B4: ='Device Selection'!$B$5/('Device Selection'!$B$5+(('Device Selection'!$B$30)+('Device Selection'!$B$20*6*(('Device Selection'!$G$7+'Device Selection'!$G$8)/1000)*('Device Selection'!$B$21/'Device Selection'!$G$9)*('Device Selection'!$B$25/'Device Selection'!$G$10)*(B3*1000))+('Device Selection'!$B$32))/1000) -> 0.99337279 | C4: ='Device Selection'!$B$5/('Device Selection'!$B$5+(('Device Selection'!$B$30)+('Device Selection'!$B$20*6*(('Device Selection'!$G$7+'Device Selection'!$G$8)/1000)*('Device Selection'!$B$21/'Device Selection'!$G$9)*('Device Selection'!$B$25/'Device Selection'!$G$10)*(C3*1000))+('Device Selection'!$B$32))/1000) -> 0.99286418 | D4: ='Device Selection'!$B$5/('Device Selection'!$B$5+(('Device Selection'!$B$30)+('Device Selection'!$B$20*6*(('Device Selection'!$G$7+'Device Selection'!$G$8)/1000)*('Device Selection'!$B$21/'Device Selection'!$G$9)*('Device Selection'!$B$25/'Device Selection'!$G$10)*(D3*1000))+('Device Selection'!$B$32))/1000) -> 0.99235609 | E4: ='Device Selection'!$B$5/('Device Selection'!$B$5+(('Device Selection'!$B$30)+('Device Selection'!$B$20*6*(('Device Selection'!$G$7+'Device Selection'!$G$8)/1000)*('Device Selection'!$B$21/'Device Selection'!$G$9)*('Device Selection'!$B$25/'Device Selection'!$G$10)*(E3*1000))+('Device Selection'!$B$32))/1000) -> 0.99184852 | F4: ='Device Selection'!$B$5/('Device Selection'!$B$5+(('Device Selection'!$B$30)+('Device Selection'!$B$20*6*(('Device Selection'!$G$7+'Device Selection'!$G$8)/1000)*('Device Selection'!$B$21/'Device Selection'!$G$9)*('Device Selection'!$B$25/'Device Selection'!$G$10)*(F3*1000))+('Device Selection'!$B$32))/1000) -> 0.99083494 | G4: ='Device Selection'!$B$5/('Device Selection'!$B$5+(('Device Selection'!$B$30)+('Device Selection'!$B$20*6*(('Device Selection'!$G$7+'Device Selection'!$G$8)/1000)*('Device Selection'!$B$21/'Device Selection'!$G$9)*('Device Selection'!$B$25/'Device Selection'!$G$10)*(G3*1000))+('Device Selection'!$B$32))/1000) -> 0.98881398 | H4: ='Device Selection'!$B$5/('Device Selection'!$B$5+(('Device Selection'!$B$30)+('Device Selection'!$B$20*6*(('Device Selection'!$G$7+'Device Selection'!$G$8)/1000)*('Device Selection'!$B$21/'Device Selection'!$G$9)*('Device Selection'!$B$25/'Device Selection'!$G$10)*(H3*1000))+('Device Selection'!$B$32))/1000) -> 0.98379746

Sheet Assumptions & Notes
A1: Assumptions and formula notes
A2: 1. The workbook is a first-order loss estimator, not a substitute for datasheet- and waveform-based detailed loss simulation.
A3: 2. SPB module voltage is calculated as total DC-link voltage divided by the number of series SPB modules.
A4: 3. Fundamental module line-line RMS voltage is approximated as 0.612·m·Vdc,module for a two-level three-phase bridge.
A5: 4. Phase current is estimated from Pmodule = √3·VLL,rms,module·Iphase,rms·power factor.
A6: 5. Conduction loss is approximated as N·3·Irms²·Rds(on), assuming MOSFET conduction and sinusoidal current.
A7: 6. Switching loss is approximated as 6·N·(Eon+Eoff scaled)·fsw. Eon/Eoff are per switch and entered in mJ.
A8: 7. Switching energy scaling uses (Vmodule/Vref)^aV·(Irms/Iref)^aI. Keep both exponents at 1 for linear scaling.
A9: 8. The calculator ignores diode reverse recovery, dead-time conduction, temperature dependence of Rds(on), gate-drive losses unless entered as fixed losses, capacitor losses, machine losses, and thermal derating.
A10: 9. Literature context: SPB is based on dc-side cascading of conventional two-level three-phase inverter bridges, enabling low-voltage devices and modularity; the uploaded literature survey contains notes on this SPB concept and loss-analysis papers.
A11: 10. Source note: user-provided literature survey PowerPoint: /mnt/data/immd_literature2020.pptx
A13: Updated workbook adds 'Device Selection' and 'Selection Sweep' sheets for automatic SPB series/parallel device selection from datasheet voltage, current, switching-loss, Rds(on), and thermal parameters.

Sheet Device Selection
A1: SPB Device Selection and Loss Calculator
A3: System / SPB targets | F3: Device datasheet inputs | K3: Model assumptions
A4: DC-link voltage, Vdc | B4: 1200 | C4: V | D4: Total input DC voltage. | F4: Device blocking voltage rating | G4: 200 | H4: V | I4: VDS/VCE rating from datasheet. | K4: 1) Each SPB submodule is modeled as a conventional two-level three-phase bridge with six switch positions.
A5: Output power, Pout | B5: 300 | C5: kW | D5: Mechanical/electrical output power used for inverter efficiency. | F5: Device continuous current rating | G5: 100 | H5: A | I5: Use comparable cooling condition from datasheet. | K5: 2) Voltage sharing is assumed ideal: Vmodule = Vdc/Ns.
A6: Power factor | B6: 0.95 | C6: - | D6: Used to estimate phase RMS current. | F6: Rds(on) | G6: 5 | H6: mΩ | I6: MOSFET on-state resistance at selected temperature. | K6: 3) Power sharing among series SPB modules is assumed equal: Pmodule = Pout/Ns.
A7: Modulation index | B7: 1 | C7: - | D7: Approx. VLL,rms = m · Vmodule / √2. | F7: Eon | G7: 0.1 | H7: mJ | I7: Turn-on energy at reference V/I. | K7: 4) Phase RMS current is estimated from Pmodule, module VLL,rms, and power factor.
A8: Voltage design margin | B8: 0.2 | C8: pu | D8: Required device voltage rating margin above module DC voltage. | F8: Eoff | G8: 0.1 | H8: mJ | I8: Turn-off energy at reference V/I. | K8: 5) Conduction loss approximation: Pcond,total = Ns · 3 · Iphase,rms² · Rds(on)/Np.
A9: Current design margin | B9: 0.2 | C9: pu | D9: Required current margin above estimated phase RMS current. | F9: Datasheet test voltage, Vref | G9: 100 | H9: V | I9: Reference voltage for switching-energy scaling. | K9: 6) Switching energy is linearly scaled with voltage and current from datasheet Eon/Eoff reference values.
A10: Ambient / coolant temperature | B10: 70 | C10: °C | D10: Thermal reference temperature. | F10: Datasheet test current, Iref | G10: 100 | H10: A | I10: Reference current for switching-energy scaling. | K10: 7) Total switching loss is nearly independent of Np under linear current scaling, but per-device thermal stress decreases with Np.
A11: Maximum junction temperature | B11: 150 | C11: °C | D11: Thermal limit for selected device. | F11: Switching frequency | G11: 100 | H11: kHz | I11: Per-device switching frequency. | K11: 8) Thermal model includes a shared sink-to-ambient path per SPB module and per-device junction/case/TIM path.
A12: Override series count | B12: 0 | C12: - | D12: 0 = automatic. Otherwise force Ns. | F12: Rth junction-to-case | G12: 0.05 | H12: °C/W | I12: Thermal resistance per physical die/module. | K12: 9) Replace formulas if your datasheet uses nonlinear Eon/Eoff curves or temperature-dependent Rds(on).
A13: Override parallel count | B13: 0 | C13: - | D13: 0 = automatic. Otherwise force Np. | F13: Rth case-to-sink/TIM | G13: 0.03 | H13: °C/W | I13: Thermal interface per physical die/module.
A14: Max parallel devices searched | B14: 20 | C14: - | D14: Used in the candidate table below. | F14: Rth sink-to-ambient per SPB module | G14: 0.05 | H14: °C/W | I14: Shared cooling path per SPB submodule.
A15: Fixed auxiliary loss per SPB module | B15: 0 | C15: W | D15: Gate drivers, control, capacitor ESR etc. Optional. | K15: Efficiency sweep vs. series modules and parallel devices
K16: Ns \ Np | L16: 1 | M16: 2 | N16: 3 | O16: 4 | P16: 5 | Q16: 6
K17: =$B$20+0 -> 8 | L17: =$B$5/($B$5+((K17*3*$B$26^2*($G$6/1000)/1)+(K17*6*(($G$7+$G$8)/1000)*(($B$4/K17)/$G$9)*($B$26/$G$10)*($G$11*1000))+(K17*$B$15))/1000) -> 0.99985242 | M17: =$B$5/($B$5+((K17*3*$B$26^2*($G$6/1000)/2)+(K17*6*(($G$7+$G$8)/1000)*(($B$4/K17)/$G$9)*($B$26/$G$10)*($G$11*1000))+(K17*$B$15))/1000) -> 0.99985422 | N17: =$B$5/($B$5+((K17*3*$B$26^2*($G$6/1000)/3)+(K17*6*(($G$7+$G$8)/1000)*(($B$4/K17)/$G$9)*($B$26/$G$10)*($G$11*1000))+(K17*$B$15))/1000) -> 0.99985482 | O17: =$B$5/($B$5+((K17*3*$B$26^2*($G$6/1000)/4)+(K17*6*(($G$7+$G$8)/1000)*(($B$4/K17)/$G$9)*($B$26/$G$10)*($G$11*1000))+(K17*$B$15))/1000) -> 0.99985512 | P17: =$B$5/($B$5+((K17*3*$B$26^2*($G$6/1000)/5)+(K17*6*(($G$7+$G$8)/1000)*(($B$4/K17)/$G$9)*($B$26/$G$10)*($G$11*1000))+(K17*$B$15))/1000) -> 0.9998553 | Q17: =$B$5/($B$5+((K17*3*$B$26^2*($G$6/1000)/6)+(K17*6*(($G$7+$G$8)/1000)*(($B$4/K17)/$G$9)*($B$26/$G$10)*($G$11*1000))+(K17*$B$15))/1000) -> 0.99985542
A18: Main outputs | B18: Value | C18: Unit | D18: Formula / note | K18: =$B$20+1 -> 9 | L18: =$B$5/($B$5+((K18*3*$B$26^2*($G$6/1000)/1)+(K18*6*(($G$7+$G$8)/1000)*(($B$4/K18)/$G$9)*($B$26/$G$10)*($G$11*1000))+(K18*$B$15))/1000) -> 0.99985197 | M18: =$B$5/($B$5+((K18*3*$B$26^2*($G$6/1000)/2)+(K18*6*(($G$7+$G$8)/1000)*(($B$4/K18)/$G$9)*($B$26/$G$10)*($G$11*1000))+(K18*$B$15))/1000) -> 0.999854 | N18: =$B$5/($B$5+((K18*3*$B$26^2*($G$6/1000)/3)+(K18*6*(($G$7+$G$8)/1000)*(($B$4/K18)/$G$9)*($B$26/$G$10)*($G$11*1000))+(K18*$B$15))/1000) -> 0.99985467 | O18: =$B$5/($B$5+((K18*3*$B$26^2*($G$6/1000)/4)+(K18*6*(($G$7+$G$8)/1000)*(($B$4/K18)/$G$9)*($B$26/$G$10)*($G$11*1000))+(K18*$B$15))/1000) -> 0.99985501 | P18: =$B$5/($B$5+((K18*3*$B$26^2*($G$6/1000)/5)+(K18*6*(($G$7+$G$8)/1000)*(($B$4/K18)/$G$9)*($B$26/$G$10)*($G$11*1000))+(K18*$B$15))/1000) -> 0.99985521 | Q18: =$B$5/($B$5+((K18*3*$B$26^2*($G$6/1000)/6)+(K18*6*(($G$7+$G$8)/1000)*(($B$4/K18)/$G$9)*($B$26/$G$10)*($G$11*1000))+(K18*$B$15))/1000) -> 0.99985535
A19: Required series modules by voltage | B19: =CEILING(B4*(1+B8)/G4,1) -> 8 | C19: - | D19: CEILING(Vdc·(1+margin)/Vrating) | K19: =$B$20+2 -> 10 | L19: =$B$5/($B$5+((K19*3*$B$26^2*($G$6/1000)/1)+(K19*6*(($G$7+$G$8)/1000)*(($B$4/K19)/$G$9)*($B$26/$G$10)*($G$11*1000))+(K19*$B$15))/1000) -> 0.99985152 | M19: =$B$5/($B$5+((K19*3*$B$26^2*($G$6/1000)/2)+(K19*6*(($G$7+$G$8)/1000)*(($B$4/K19)/$G$9)*($B$26/$G$10)*($G$11*1000))+(K19*$B$15))/1000) -> 0.99985377 | N19: =$B$5/($B$5+((K19*3*$B$26^2*($G$6/1000)/3)+(K19*6*(($G$7+$G$8)/1000)*(($B$4/K19)/$G$9)*($B$26/$G$10)*($G$11*1000))+(K19*$B$15))/1000) -> 0.99985452 | O19: =$B$5/($B$5+((K19*3*$B$26^2*($G$6/1000)/4)+(K19*6*(($G$7+$G$8)/1000)*(($B$4/K19)/$G$9)*($B$26/$G$10)*($G$11*1000))+(K19*$B$15))/1000) -> 0.9998549 | P19: =$B$5/($B$5+((K19*3*$B$26^2*($G$6/1000)/5)+(K19*6*(($G$7+$G$8)/1000)*(($B$4/K19)/$G$9)*($B$26/$G$10)*($G$11*1000))+(K19*$B$15))/1000) -> 0.99985512 | Q19: =$B$5/($B$5+((K19*3*$B$26^2*($G$6/1000)/6)+(K19*6*(($G$7+$G$8)/1000)*(($B$4/K19)/$G$9)*($B$26/$G$10)*($G$11*1000))+(K19*$B$15))/1000) -> 0.99985527
A20: Selected series modules, Ns | B20: =IF(B12>0,B12,B19) -> 8 | C20: - | D20: Auto or override | K20: =$B$20+3 -> 11 | L20: =$B$5/($B$5+((K20*3*$B$26^2*($G$6/1000)/1)+(K20*6*(($G$7+$G$8)/1000)*(($B$4/K20)/$G$9)*($B$26/$G$10)*($G$11*1000))+(K20*$B$15))/1000) -> 0.99985107 | M20: =$B$5/($B$5+((K20*3*$B$26^2*($G$6/1000)/2)+(K20*6*(($G$7+$G$8)/1000)*(($B$4/K20)/$G$9)*($B$26/$G$10)*($G$11*1000))+(K20*$B$15))/1000) -> 0.99985355 | N20: =$B$5/($B$5+((K20*3*$B$26^2*($G$6/1000)/3)+(K20*6*(($G$7+$G$8)/1000)*(($B$4/K20)/$G$9)*($B$26/$G$10)*($G$11*1000))+(K20*$B$15))/1000) -> 0.99985437 | O20: =$B$5/($B$5+((K20*3*$B$26^2*($G$6/1000)/4)+(K20*6*(($G$7+$G$8)/1000)*(($B$4/K20)/$G$9)*($B$26/$G$10)*($G$11*1000))+(K20*$B$15))/1000) -> 0.99985478 | P20: =$B$5/($B$5+((K20*3*$B$26^2*($G$6/1000)/5)+(K20*6*(($G$7+$G$8)/1000)*(($B$4/K20)/$G$9)*($B$26/$G$10)*($G$11*1000))+(K20*$B$15))/1000) -> 0.99985503 | Q20: =$B$5/($B$5+((K20*3*$B$26^2*($G$6/1000)/6)+(K20*6*(($G$7+$G$8)/1000)*(($B$4/K20)/$G$9)*($B$26/$G$10)*($G$11*1000))+(K20*$B$15))/1000) -> 0.9998552
A21: Module DC voltage | B21: =B4/B20 -> 150 | C21: V | D21: Vdc / Ns | K21: =$B$20+4 -> 12 | L21: =$B$5/($B$5+((K21*3*$B$26^2*($G$6/1000)/1)+(K21*6*(($G$7+$G$8)/1000)*(($B$4/K21)/$G$9)*($B$26/$G$10)*($G$11*1000))+(K21*$B$15))/1000) -> 0.99985062 | M21: =$B$5/($B$5+((K21*3*$B$26^2*($G$6/1000)/2)+(K21*6*(($G$7+$G$8)/1000)*(($B$4/K21)/$G$9)*($B$26/$G$10)*($G$11*1000))+(K21*$B$15))/1000) -> 0.99985332 | N21: =$B$5/($B$5+((K21*3*$B$26^2*($G$6/1000)/3)+(K21*6*(($G$7+$G$8)/1000)*(($B$4/K21)/$G$9)*($B$26/$G$10)*($G$11*1000))+(K21*$B$15))/1000) -> 0.99985422 | O21: =$B$5/($B$5+((K21*3*$B$26^2*($G$6/1000)/4)+(K21*6*(($G$7+$G$8)/1000)*(($B$4/K21)/$G$9)*($B$26/$G$10)*($G$11*1000))+(K21*$B$15))/1000) -> 0.99985467 | P21: =$B$5/($B$5+((K21*3*$B$26^2*($G$6/1000)/5)+(K21*6*(($G$7+$G$8)/1000)*(($B$4/K21)/$G$9)*($B$26/$G$10)*($G$11*1000))+(K21*$B$15))/1000) -> 0.99985494 | Q21: =$B$5/($B$5+((K21*3*$B$26^2*($G$6/1000)/6)+(K21*6*(($G$7+$G$8)/1000)*(($B$4/K21)/$G$9)*($B$26/$G$10)*($G$11*1000))+(K21*$B$15))/1000) -> 0.99985512
A22: Suggested device voltage rating | B22: =B21*(1+B8) -> 180 | C22: V | D22: Vmodule·(1+margin) | K22: =$B$20+5 -> 13 | L22: =$B$5/($B$5+((K22*3*$B$26^2*($G$6/1000)/1)+(K22*6*(($G$7+$G$8)/1000)*(($B$4/K22)/$G$9)*($B$26/$G$10)*($G$11*1000))+(K22*$B$15))/1000) -> 0.99985017 | M22: =$B$5/($B$5+((K22*3*$B$26^2*($G$6/1000)/2)+(K22*6*(($G$7+$G$8)/1000)*(($B$4/K22)/$G$9)*($B$26/$G$10)*($G$11*1000))+(K22*$B$15))/1000) -> 0.9998531 | N22: =$B$5/($B$5+((K22*3*$B$26^2*($G$6/1000)/3)+(K22*6*(($G$7+$G$8)/1000)*(($B$4/K22)/$G$9)*($B$26/$G$10)*($G$11*1000))+(K22*$B$15))/1000) -> 0.99985407 | O22: =$B$5/($B$5+((K22*3*$B$26^2*($G$6/1000)/4)+(K22*6*(($G$7+$G$8)/1000)*(($B$4/K22)/$G$9)*($B$26/$G$10)*($G$11*1000))+(K22*$B$15))/1000) -> 0.99985456 | P22: =$B$5/($B$5+((K22*3*$B$26^2*($G$6/1000)/5)+(K22*6*(($G$7+$G$8)/1000)*(($B$4/K22)/$G$9)*($B$26/$G$10)*($G$11*1000))+(K22*$B$15))/1000) -> 0.99985485 | Q22: =$B$5/($B$5+((K22*3*$B$26^2*($G$6/1000)/6)+(K22*6*(($G$7+$G$8)/1000)*(($B$4/K22)/$G$9)*($B$26/$G$10)*($G$11*1000))+(K22*$B$15))/1000) -> 0.99985505
A23: Approx. total VLL,rms | B23: =B7*B4/SQRT(2) -> 848.52814 | C23: V | D23: m·Vdc/√2 | K23: =$B$20+6 -> 14 | L23: =$B$5/($B$5+((K23*3*$B$26^2*($G$6/1000)/1)+(K23*6*(($G$7+$G$8)/1000)*(($B$4/K23)/$G$9)*($B$26/$G$10)*($G$11*1000))+(K23*$B$15))/1000) -> 0.99984972 | M23: =$B$5/($B$5+((K23*3*$B$26^2*($G$6/1000)/2)+(K23*6*(($G$7+$G$8)/1000)*(($B$4/K23)/$G$9)*($B$26/$G$10)*($G$11*1000))+(K23*$B$15))/1000) -> 0.99985287 | N23: =$B$5/($B$5+((K23*3*$B$26^2*($G$6/1000)/3)+(K23*6*(($G$7+$G$8)/1000)*(($B$4/K23)/$G$9)*($B$26/$G$10)*($G$11*1000))+(K23*$B$15))/1000) -> 0.99985392 | O23: =$B$5/($B$5+((K23*3*$B$26^2*($G$6/1000)/4)+(K23*6*(($G$7+$G$8)/1000)*(($B$4/K23)/$G$9)*($B$26/$G$10)*($G$11*1000))+(K23*$B$15))/1000) -> 0.99985445 | P23: =$B$5/($B$5+((K23*3*$B$26^2*($G$6/1000)/5)+(K23*6*(($G$7+$G$8)/1000)*(($B$4/K23)/$G$9)*($B$26/$G$10)*($G$11*1000))+(K23*$B$15))/1000) -> 0.99985476 | Q23: =$B$5/($B$5+((K23*3*$B$26^2*($G$6/1000)/6)+(K23*6*(($G$7+$G$8)/1000)*(($B$4/K23)/$G$9)*($B$26/$G$10)*($G$11*1000))+(K23*$B$15))/1000) -> 0.99985497
A24: Approx. module VLL,rms | B24: =B7*B21/SQRT(2) -> 106.06602 | C24: V | D24: m·Vmodule/√2 | K24: =$B$20+7 -> 15 | L24: =$B$5/($B$5+((K24*3*$B$26^2*($G$6/1000)/1)+(K24*6*(($G$7+$G$8)/1000)*(($B$4/K24)/$G$9)*($B$26/$G$10)*($G$11*1000))+(K24*$B$15))/1000) -> 0.99984927 | M24: =$B$5/($B$5+((K24*3*$B$26^2*($G$6/1000)/2)+(K24*6*(($G$7+$G$8)/1000)*(($B$4/K24)/$G$9)*($B$26/$G$10)*($G$11*1000))+(K24*$B$15))/1000) -> 0.99985265 | N24: =$B$5/($B$5+((K24*3*$B$26^2*($G$6/1000)/3)+(K24*6*(($G$7+$G$8)/1000)*(($B$4/K24)/$G$9)*($B$26/$G$10)*($G$11*1000))+(K24*$B$15))/1000) -> 0.99985377 | O24: =$B$5/($B$5+((K24*3*$B$26^2*($G$6/1000)/4)+(K24*6*(($G$7+$G$8)/1000)*(($B$4/K24)/$G$9)*($B$26/$G$10)*($G$11*1000))+(K24*$B$15))/1000) -> 0.99985433 | P24: =$B$5/($B$5+((K24*3*$B$26^2*($G$6/1000)/5)+(K24*6*(($G$7+$G$8)/1000)*(($B$4/K24)/$G$9)*($B$26/$G$10)*($G$11*1000))+(K24*$B$15))/1000) -> 0.99985467 | Q24: =$B$5/($B$5+((K24*3*$B$26^2*($G$6/1000)/6)+(K24*6*(($G$7+$G$8)/1000)*(($B$4/K24)/$G$9)*($B$26/$G$10)*($G$11*1000))+(K24*$B$15))/1000) -> 0.9998549
A25: Estimated module phase current | B25: =B5*1000/B20/(SQRT(3)*B24*B6) -> 214.86752 | C25: Arms | D25: Pmodule/(√3·VLL,module·PF) | K25: =$B$20+8 -> 16 | L25: =$B$5/($B$5+((K25*3*$B$26^2*($G$6/1000)/1)+(K25*6*(($G$7+$G$8)/1000)*(($B$4/K25)/$G$9)*($B$26/$G$10)*($G$11*1000))+(K25*$B$15))/1000) -> 0.99984882 | M25: =$B$5/($B$5+((K25*3*$B$26^2*($G$6/1000)/2)+(K25*6*(($G$7+$G$8)/1000)*(($B$4/K25)/$G$9)*($B$26/$G$10)*($G$11*1000))+(K25*$B$15))/1000) -> 0.99985242 | N25: =$B$5/($B$5+((K25*3*$B$26^2*($G$6/1000)/3)+(K25*6*(($G$7+$G$8)/1000)*(($B$4/K25)/$G$9)*($B$26/$G$10)*($G$11*1000))+(K25*$B$15))/1000) -> 0.99985362 | O25: =$B$5/($B$5+((K25*3*$B$26^2*($G$6/1000)/4)+(K25*6*(($G$7+$G$8)/1000)*(($B$4/K25)/$G$9)*($B$26/$G$10)*($G$11*1000))+(K25*$B$15))/1000) -> 0.99985422 | P25: =$B$5/($B$5+((K25*3*$B$26^2*($G$6/1000)/5)+(K25*6*(($G$7+$G$8)/1000)*(($B$4/K25)/$G$9)*($B$26/$G$10)*($G$11*1000))+(K25*$B$15))/1000) -> 0.99985458 | Q25: =$B$5/($B$5+((K25*3*$B$26^2*($G$6/1000)/6)+(K25*6*(($G$7+$G$8)/1000)*(($B$4/K25)/$G$9)*($B$26/$G$10)*($G$11*1000))+(K25*$B$15))/1000) -> 0.99985482
A26: Required parallel devices by current | B26: =CEILING(B25*(1+B9)/G5,1) -> 3 | C26: - | D26: CEILING(Iphase·(1+margin)/Irating) | K26: =$B$20+9 -> 17 | L26: =$B$5/($B$5+((K26*3*$B$26^2*($G$6/1000)/1)+(K26*6*(($G$7+$G$8)/1000)*(($B$4/K26)/$G$9)*($B$26/$G$10)*($G$11*1000))+(K26*$B$15))/1000) -> 0.99984837 | M26: =$B$5/($B$5+((K26*3*$B$26^2*($G$6/1000)/2)+(K26*6*(($G$7+$G$8)/1000)*(($B$4/K26)/$G$9)*($B$26/$G$10)*($G$11*1000))+(K26*$B$15))/1000) -> 0.9998522 | N26: =$B$5/($B$5+((K26*3*$B$26^2*($G$6/1000)/3)+(K26*6*(($G$7+$G$8)/1000)*(($B$4/K26)/$G$9)*($B$26/$G$10)*($G$11*1000))+(K26*$B$15))/1000) -> 0.99985347 | O26: =$B$5/($B$5+((K26*3*$B$26^2*($G$6/1000)/4)+(K26*6*(($G$7+$G$8)/1000)*(($B$4/K26)/$G$9)*($B$26/$G$10)*($G$11*1000))+(K26*$B$15))/1000) -> 0.99985411 | P26: =$B$5/($B$5+((K26*3*$B$26^2*($G$6/1000)/5)+(K26*6*(($G$7+$G$8)/1000)*(($B$4/K26)/$G$9)*($B$26/$G$10)*($G$11*1000))+(K26*$B$15))/1000) -> 0.99985449 | Q26: =$B$5/($B$5+((K26*3*$B$26^2*($G$6/1000)/6)+(K26*6*(($G$7+$G$8)/1000)*(($B$4/K26)/$G$9)*($B$26/$G$10)*($G$11*1000))+(K26*$B$15))/1000) -> 0.99985475
A27: Required parallel devices by current+thermal | B27: =IFERROR(MAX(B26,INDEX(A48:A67,MATCH(1,H48:H67,0))),"No thermal solution") -> 3 | C27: - | D27: Smallest Np satisfying candidate table
A28: Selected parallel devices, Np | B28: =IF(B13>0,B13,B27) -> 3 | C28: - | D28: Auto or override
A29: Effective Rds per switch position | B29: =IF(ISNUMBER(B28),G6/B28,"") -> 1.6666667 | C29: mΩ | D29: Rds/Np
A30: Total conduction loss | B30: =IF(ISNUMBER(B28),B20*3*B25^2*(G6/1000)/B28,"") -> 1846.7221 | C30: W | D30: Ns·3·I²·Rds/Np
A31: Total switching loss | B31: =B20*6*((G7+G8)/1000)*(B21/G9)*(B25/G10)*(G11*1000) -> 3094.0923 | C31: W | D31: Ns·6·Esw_scaled·fsw
A32: Total auxiliary loss | B32: =B20*B15 -> 0 | C32: W | D32: Ns·fixed auxiliary loss
A33: Total inverter loss | B33: =SUM(B30:B32) -> 4940.8144 | C33: W | D33: Sum of conduction, switching, auxiliary
A34: Input power | B34: =B5+B33/1000 -> 304.94081 | C34: kW | D34: Pout + losses
A35: Efficiency | B35: =B5/B34 -> 0.98379746 | C35: % | D35: Pout/(Pout+losses)
A36: Estimated junction temperature | B36: =IF(ISNUMBER(B28),B10 + (B30/B20+B31/B20+B32/B20)*G14 + ((B30+B31)/B20/(6*B28))*(G12+G13),"") -> 103.62499 | C36: °C | D36: Worst physical device in selected module
A37: Thermal status | B37: =IF(AND(ISNUMBER(B36),B36<=B11),"OK","Check thermal") -> OK | D37: OK if Tj <= limit
A38: Current rating status | B38: =IF(AND(ISNUMBER(B28),B25*(1+B9)/B28<=G5),"OK","Increase Np") -> OK | D38: OK if current per parallel device incl. margin <= rating
A47: Np candidate | B47: Device current | C47: Rds_eff | D47: Pcond/module | E47: Psw/module | F47: Aux/module | G47: Tj estimate | H47: OK?
A48: 1 | B48: =$B$25/A48 -> 214.86752 | C48: =$G$6/A48 -> 5 | D48: =3*$B$25^2*($G$6/1000)/A48 -> 692.52078 | E48: =6*(($G$7+$G$8)/1000)*($B$21/$G$9)*($B$25/$G$10)*($G$11*1000) -> 386.76154 | F48: =$B$15 -> 0 | G48: =$B$10 + (D48+E48+F48)*$G$14 + ((D48+E48)/(6*A48))*($G$12+$G$13) -> 138.35455 | H48: =IF(AND(A48>=$B$26,G48<=$B$11),1,0) -> 0
A49: 2 | B49: =$B$25/A49 -> 107.43376 | C49: =$G$6/A49 -> 2.5 | D49: =3*$B$25^2*($G$6/1000)/A49 -> 346.26039 | E49: =6*(($G$7+$G$8)/1000)*($B$21/$G$9)*($B$25/$G$10)*($G$11*1000) -> 386.76154 | F49: =$B$15 -> 0 | G49: =$B$10 + (D49+E49+F49)*$G$14 + ((D49+E49)/(6*A49))*($G$12+$G$13) -> 111.53791 | H49: =IF(AND(A49>=$B$26,G49<=$B$11),1,0) -> 0
...

Sheet Selection Sweep
A1: SPB Selection Sweep
A3: Ns | B3: Np | C3: Vmodule (V) | D3: Iphase (Arms) | E3: Total loss (W) | F3: Efficiency | G3: Tj (°C) | H3: Status
A4: 1 | B4: 1 | C4: ='Device Selection'!$B$4/A4 -> 1200 | D4: ='Device Selection'!$B$5*1000/A4/(SQRT(3)*('Device Selection'!$B$7*(C4)/SQRT(2))*'Device Selection'!$B$6) -> 214.86752 | E4: =A4*3*D4^2*('Device Selection'!$G$6/1000)/B4+A4*6*(('Device Selection'!$G$7+'Device Selection'!$G$8)/1000)*(C4/'Device Selection'!$G$9)*(D4/'Device Selection'!$G$10)*('Device Selection'!$G$11*1000)+A4*'Device Selection'!$B$15 -> 3786.6131 | F4: ='Device Selection'!$B$5/('Device Selection'!$B$5+E4/1000) -> 0.98753529 | G4: ='Device Selection'!$B$10 + (E4/A4)*'Device Selection'!$G$14 + ((E4/A4-'Device Selection'!$B$15)/(6*B4))*('Device Selection'!$G$12+'Device Selection'!$G$13) -> 309.81883 | H4: =IF(AND(C4*(1+'Device Selection'!$B$8)<='Device Selection'!$G$4,D4*(1+'Device Selection'!$B$9)/B4<='Device Selection'!$G$5,G4<='Device Selection'!$B$11),"OK","")
A5: 1 | B5: 2 | C5: ='Device Selection'!$B$4/A5 -> 1200 | D5: ='Device Selection'!$B$5*1000/A5/(SQRT(3)*('Device Selection'!$B$7*(C5)/SQRT(2))*'Device Selection'!$B$6) -> 214.86752 | E5: =A5*3*D5^2*('Device Selection'!$G$6/1000)/B5+A5*6*(('Device Selection'!$G$7+'Device Selection'!$G$8)/1000)*(C5/'Device Selection'!$G$9)*(D5/'Device Selection'!$G$10)*('Device Selection'!$G$11*1000)+A5*'Device Selection'!$B$15 -> 3440.3527 | F5: ='Device Selection'!$B$5/('Device Selection'!$B$5+E5/1000) -> 0.98866218 | G5: ='Device Selection'!$B$10 + (E5/A5)*'Device Selection'!$G$14 + ((E5/A5-'Device Selection'!$B$15)/(6*B5))*('Device Selection'!$G$12+'Device Selection'!$G$13) -> 264.95332 | H5: =IF(AND(C5*(1+'Device Selection'!$B$8)<='Device Selection'!$G$4,D5*(1+'Device Selection'!$B$9)/B5<='Device Selection'!$G$5,G5<='Device Selection'!$B$11),"OK","")
A6: 1 | B6: 3 | C6: ='Device Selection'!$B$4/A6 -> 1200 | D6: ='Device Selection'!$B$5*1000/A6/(SQRT(3)*('Device Selection'!$B$7*(C6)/SQRT(2))*'Device Selection'!$B$6) -> 214.86752 | E6: =A6*3*D6^2*('Device Selection'!$G$6/1000)/B6+A6*6*(('Device Selection'!$G$7+'Device Selection'!$G$8)/1000)*(C6/'Device Selection'!$G$9)*(D6/'Device Selection'!$G$10)*('Device Selection'!$G$11*1000)+A6*'Device Selection'!$B$15 -> 3324.9326 | F6: ='Device Selection'!$B$5/('Device Selection'!$B$5+E6/1000) -> 0.98903838 | G6: ='Device Selection'!$B$10 + (E6/A6)*'Device Selection'!$G$14 + ((E6/A6-'Device Selection'!$B$15)/(6*B6))*('Device Selection'!$G$12+'Device Selection'!$G$13) -> 251.02411 | H6: =IF(AND(C6*(1+'Device Selection'!$B$8)<='Device Selection'!$G$4,D6*(1+'Device Selection'!$B$9)/B6<='Device Selection'!$G$5,G6<='Device Selection'!$B$11),"OK","")
A7: 1 | B7: 4 | C7: ='Device Selection'!$B$4/A7 -> 1200 | D7: ='Device Selection'!$B$5*1000/A7/(SQRT(3)*('Device Selection'!$B$7*(C7)/SQRT(2))*'Device Selection'!$B$6) -> 214.86752 | E7: =A7*3*D7^2*('Device Selection'!$G$6/1000)/B7+A7*6*(('Device Selection'!$G$7+'Device Selection'!$G$8)/1000)*(C7/'Device Selection'!$G$9)*(D7/'Device Selection'!$G$10)*('Device Selection'!$G$11*1000)+A7*'Device Selection'!$B$15 -> 3267.2225 | F7: ='Device Selection'!$B$5/('Device Selection'!$B$5+E7/1000) -> 0.98922659 | G7: ='Device Selection'!$B$10 + (E7/A7)*'Device Selection'!$G$14 + ((E7/A7-'Device Selection'!$B$15)/(6*B7))*('Device Selection'!$G$12+'Device Selection'!$G$13) -> 244.25187 | H7: =IF(AND(C7*(1+'Device Selection'!$B$8)<='Device Selection'!$G$4,D7*(1+'Device Selection'!$B$9)/B7<='Device Selection'!$G$5,G7<='Device Selection'!$B$11),"OK","")
A8: 1 | B8: 5 | C8: ='Device Selection'!$B$4/A8 -> 1200 | D8: ='Device Selection'!$B$5*1000/A8/(SQRT(3)*('Device Selection'!$B$7*(C8)/SQRT(2))*'Device Selection'!$B$6) -> 214.86752 | E8: =A8*3*D8^2*('Device Selection'!$G$6/1000)/B8+A8*6*(('Device Selection'!$G$7+'Device Selection'!$G$8)/1000)*(C8/'Device Selection'!$G$9)*(D8/'Device Selection'!$G$10)*('Device Selection'!$G$11*1000)+A8*'Device Selection'!$B$15 -> 3232.5965 | F8: ='Device Selection'!$B$5/('Device Selection'!$B$5+E8/1000) -> 0.98933955 | G8: ='Device Selection'!$B$10 + (E8/A8)*'Device Selection'!$G$14 + ((E8/A8-'Device Selection'!$B$15)/(6*B8))*('Device Selection'!$G$12+'Device Selection'!$G$13) -> 240.25008 | H8: =IF(AND(C8*(1+'Device Selection'!$B$8)<='Device Selection'!$G$4,D8*(1+'Device Selection'!$B$9)/B8<='Device Selection'!$G$5,G8<='Device Selection'!$B$11),"OK","")
A9: 1 | B9: 6 | C9: ='Device Selection'!$B$4/A9 -> 1200 | D9: ='Device Selection'!$B$5*1000/A9/(SQRT(3)*('Device Selection'!$B$7*(C9)/SQRT(2))*'Device Selection'!$B$6) -> 214.86752 | E9: =A9*3*D9^2*('Device Selection'!$G$6/1000)/B9+A9*6*(('Device Selection'!$G$7+'Device Selection'!$G$8)/1000)*(C9/'Device Selection'!$G$9)*(D9/'Device Selection'!$G$10)*('Device Selection'!$G$11*1000)+A9*'Device Selection'!$B$15 -> 3209.5124 | F9: ='Device Selection'!$B$5/('Device Selection'!$B$5+E9/1000) -> 0.98941487 | G9: ='Device Selection'!$B$10 + (E9/A9)*'Device Selection'!$G$14 + ((E9/A9-'Device Selection'!$B$15)/(6*B9))*('Device Selection'!$G$12+'Device Selection'!$G$13) -> 237.60787 | H9: =IF(AND(C9*(1+'Device Selection'!$B$8)<='Device Selection'!$G$4,D9*(1+'Device Selection'!$B$9)/B9<='Device Selection'!$G$5,G9<='Device Selection'!$B$11),"OK","")
A10: 1 | B10: 7 | C10: ='Device Selection'!$B$4/A10 -> 1200 | D10: ='Device Selection'!$B$5*1000/A10/(SQRT(3)*('Device Selection'!$B$7*(C10)/SQRT(2))*'Device Selection'!$B$6) -> 214.86752 | E10: =A10*3*D10^2*('Device Selection'!$G$6/1000)/B10+A10*6*(('Device Selection'!$G$7+'Device Selection'!$G$8)/1000)*(C10/'Device Selection'!$G$9)*(D10/'Device Selection'!$G$10)*('Device Selection'!$G$11*1000)+A10*'Device Selection'!$B$15 -> 3193.0238 | F10: ='Device Selection'!$B$5/('Device Selection'!$B$5+E10/1000) -> 0.98946868 | G10: ='Device Selection'!$B$10 + (E10/A10)*'Device Selection'!$G$14 + ((E10/A10-'Device Selection'!$B$15)/(6*B10))*('Device Selection'!$G$12+'Device Selection'!$G$13) -> 235.73314 | H10: =IF(AND(C10*(1+'Device Selection'!$B$8)<='Device Selection'!$G$4,D10*(1+'Device Selection'!$B$9)/B10<='Device Selection'!$G$5,G10<='Device Selection'!$B$11),"OK","")
A11: 1 | B11: 8 | C11: ='Device Selection'!$B$4/A11 -> 1200 | D11: ='Device Selection'!$B$5*1000/A11/(SQRT(3)*('Device Selection'!$B$7*(C11)/SQRT(2))*'Device Selection'!$B$6) -> 214.86752 | E11: =A11*3*D11^2*('Device Selection'!$G$6/1000)/B11+A11*6*(('Device Selection'!$G$7+'Device Selection'!$G$8)/1000)*(C11/'Device Selection'!$G$9)*(D11/'Device Selection'!$G$10)*('Device Selection'!$G$11*1000)+A11*'Device Selection'!$B$15 -> 3180.6574 | F11: ='Device Selection'!$B$5/('Device Selection'!$B$5+E11/1000) -> 0.98950904 | G11: ='Device Selection'!$B$10 + (E11/A11)*'Device Selection'!$G$14 + ((E11/A11-'Device Selection'!$B$15)/(6*B11))*('Device Selection'!$G$12+'Device Selection'!$G$13) -> 234.33397 | H11: =IF(AND(C11*(1+'Device Selection'!$B$8)<='Device Selection'!$G$4,D11*(1+'Device Selection'!$B$9)/B11<='Device Selection'!$G$5,G11<='Device Selection'!$B$11),"OK","")
A12: 1 | B12: 9 | C12: ='Device Selection'!$B$4/A12 -> 1200 | D12: ='Device Selection'!$B$5*1000/A12/(SQRT(3)*('Device Selection'!$B$7*(C12)/SQRT(2))*'Device Selection'!$B$6) -> 214.86752 | E12: =A12*3*D12^2*('Device Selection'!$G$6/1000)/B12+A12*6*(('Device Selection'!$G$7+'Device Selection'!$G$8)/1000)*(C12/'Device Selection'!$G$9)*(D12/'Device Selection'!$G$10)*('Device Selection'!$G$11*1000)+A12*'Device Selection'!$B$15 -> 3171.0391 | F12: ='Device Selection'!$B$5/('Device Selection'!$B$5+E12/1000) -> 0.98954043 | G12: ='Device Selection'!$B$10 + (E12/A12)*'Device Selection'!$G$14 + ((E12/A12-'Device Selection'!$B$15)/(6*B12))*('Device Selection'!$G$12+'Device Selection'!$G$13) -> 233.24979 | H12: =IF(AND(C12*(1+'Device Selection'!$B$8)<='Device Selection'!$G$4,D12*(1+'Device Selection'!$B$9)/B12<='Device Selection'!$G$5,G12<='Device Selection'!$B$11),"OK","")
A13: 1 | B13: 10 | C13: ='Device Selection'!$B$4/A13 -> 1200 | D13: ='Device Selection'!$B$5*1000/A13/(SQRT(3)*('Device Selection'!$B$7*(C13)/SQRT(2))*'Device Selection'!$B$6) -> 214.86752 | E13: =A13*3*D13^2*('Device Selection'!$G$6/1000)/B13+A13*6*(('Device Selection'!$G$7+'Device Selection'!$G$8)/1000)*(C13/'Device Selection'!$G$9)*(D13/'Device Selection'!$G$10)*('Device Selection'!$G$11*1000)+A13*'Device Selection'!$B$15 -> 3163.3444 | F13: ='Device Selection'!$B$5/('Device Selection'!$B$5+E13/1000) -> 0.98956554 | G13: ='Device Selection'!$B$10 + (E13/A13)*'Device Selection'!$G$14 + ((E13/A13-'Device Selection'!$B$15)/(6*B13))*('Device Selection'!$G$12+'Device Selection'!$G$13) -> 232.38501 | H13: =IF(AND(C13*(1+'Device Selection'!$B$8)<='Device Selection'!$G$4,D13*(1+'Device Selection'!$B$9)/B13<='Device Selection'!$G$5,G13<='Device Selection'!$B$11),"OK","")
A14: 2 | B14: 1 | C14: ='Device Selection'!$B$4/A14 -> 600 | D14: ='Device Selection'!$B$5*1000/A14/(SQRT(3)*('Device Selection'!$B$7*(C14)/SQRT(2))*'Device Selection'!$B$6) -> 214.86752 | E14: =A14*3*D14^2*('Device Selection'!$G$6/1000)/B14+A14*6*(('Device Selection'!$G$7+'Device Selection'!$G$8)/1000)*(C14/'Device Selection'!$G$9)*(D14/'Device Selection'!$G$10)*('Device Selection'!$G$11*1000)+A14*'Device Selection'!$B$15 -> 4479.1339 | F14: ='Device Selection'!$B$5/('Device Selection'!$B$5+E14/1000) -> 0.98528919 | G14: ='Device Selection'!$B$10 + (E14/A14)*'Device Selection'!$G$14 + ((E14/A14-'Device Selection'!$B$15)/(6*B14))*('Device Selection'!$G$12+'Device Selection'!$G$13) -> 211.83924 | H14: =IF(AND(C14*(1+'Device Selection'!$B$8)<='Device Selection'!$G$4,D14*(1+'Device Selection'!$B$9)/B14<='Device Selection'!$G$5,G14<='Device Selection'!$B$11),"OK","")
A15: 2 | B15: 2 | C15: ='Device Selection'!$B$4/A15 -> 600 | D15: ='Device Selection'!$B$5*1000/A15/(SQRT(3)*('Device Selection'!$B$7*(C15)/SQRT(2))*'Device Selection'!$B$6) -> 214.86752 | E15: =A15*3*D15^2*('Device Selection'!$G$6/1000)/B15+A15*6*(('Device Selection'!$G$7+'Device Selection'!$G$8)/1000)*(C15/'Device Selection'!$G$9)*(D15/'Device Selection'!$G$10)*('Device Selection'!$G$11*1000)+A15*'Device Selection'!$B$15 -> 3786.6131 | F15: ='Device Selection'!$B$5/('Device Selection'!$B$5+E15/1000) -> 0.98753529 | G15: ='Device Selection'!$B$10 + (E15/A15)*'Device Selection'!$G$14 + ((E15/A15-'Device Selection'!$B$15)/(6*B15))*('Device Selection'!$G$12+'Device Selection'!$G$13) -> 177.28737 | H15: =IF(AND(C15*(1+'Device Selection'!$B$8)<='Device Selection'!$G$4,D15*(1+'Device Selection'!$B$9)/B15<='Device Selection'!$G$5,G15<='Device Selection'!$B$11),"OK","")
... A203: 20 | B203: 10 | C203: ='Device Selection'!$B$4/A203 -> 60 | D203: ='Device Selection'!$B$5*1000/A203/(SQRT(3)*('Device Selection'!$B$7*(C203)/SQRT(2))*'Device Selection'!$B$6) -> 214.86752 | E203: =A203*3*D203^2*('Device Selection'!$G$6/1000)/B203+A203*6*(('Device Selection'!$G$7+'Device Selection'!$G$8)/1000)*(C203/'Device Selection'!$G$9)*(D203/'Device Selection'!$G$10)*('Device Selection'!$G$11*1000)+A203*'Device Selection'!$B$15 -> 4479.1339 | F203: ='Device Selection'!$B$5/('Device Selection'!$B$5+E203/1000) -> 0.98528919 | G203: ='Device Selection'!$B$10 + (E203/A203)*'Device Selection'!$G$14 + ((E203/A203-'Device Selection'!$B$15)/(6*B203))*('Device Selection'!$G$12+'Device Selection'!$G$13) -> 81.496444 | H203: =IF(AND(C203*(1+'Device Selection'!$B$8)<='Device Selection'!$G$4,D203*(1+'Device Selection'!$B$9)/B203<='Device Selection'!$G$5,G203<='Device Selection'!$B$11),"OK","") -> OK
