Workbook

Sheet SPB Loss Calculator
A1: Parametric Basic Loss Calculator for SPB / Modular Three-Phase Inverter | J1: Quick Summary
A2: Enter only the yellow cells. Output cells update by formula. Energy inputs are assumed in mJ per switching event at the reference voltage/current.
J3: Module Vdc | K3: =B24 -> 150 | L3: V | M3: Efficiency | N3: =F29 -> 96.753454
A4: System inputs | J4: Device V rating | K4: =B28 -> 225 | L4: V | M4: Total loss | N4: =F27 -> 10066.451
A5: Total DC-link voltage | B5: 1200 | C5: V | D5: Total battery/DC-link voltage applied to series SPB stack | J5: Phase current | K5: =B26 -> 248.10764 | L5: Arms | M5: Cond. loss | N5: =F24 -> 7386.8883
A6: Number of series SPB modules | B6: 8 | C6: - | D6: Number of cascaded three-phase bridge submodules | J6: Switches | K6: =B30 -> 48 | L6: - | M6: Sw. loss | N6: =F26 -> 2679.5625
A7: Output power | B7: 300 | C7: kW | D7: Mechanical/electrical output power used for inverter efficiency calculation | J7: Input DC current | K7: =B27 -> 250 | L7: A | M7: Module power | N7: =B31 -> 37.5
A8: Power factor | B8: 0.95 | C8: - | D8: Used to estimate phase current from P = √3·VLL,rms·I·pf | J8: Loss / module | K8: =F27/B6 -> 1258.3064 | L8: W | M8: Loss / switch avg. | N8: =F27/B30 -> 209.71773
A9: Modulation index | B9: 1 | C9: - | D9: Sinusoidal PWM fundamental modulation index; 1.154 possible with zero-sequence extension
A10: Device voltage margin | B10: 1.5 | C10: pu | D10: Suggested device blocking rating = Vmodule × margin
A11: Device current margin | B11: 1.25 | C11: pu | D11: Suggested current rating = Irms × margin
A12: Device / switching inputs
A13: Eon per switch @ reference | B13: 0.1 | C13: mJ | D13: Turn-on energy of one device at Vref/Iref
A14: Eoff per switch @ reference | B14: 0.1 | C14: mJ | D14: Turn-off energy of one device at Vref/Iref
A15: Rds(on) per switch | B15: 5 | C15: mΩ | D15: On-state resistance of one switch at selected temperature
A16: Switching frequency | B16: 300 | C16: kHz | D16: PWM switching frequency per submodule
A17: Reference voltage for Eon/Eoff | B17: 200 | C17: V | D17: Datasheet/test voltage for switching energy
A18: Reference current for Eon/Eoff | B18: 100 | C18: A | D18: Datasheet/test current for switching energy
A19: Energy voltage exponent | B19: 1 | C19: - | D19: Use 1 for linear voltage scaling
A20: Energy current exponent | B20: 1 | C20: - | D20: Use 1 for linear current scaling
A21: Additional fixed losses | B21: 0 | C21: W | D21: Optional control/gate-drive/cooling/auxiliary losses
A23: Calculated ratings | E23: Loss results
A24: DC voltage per SPB module | B24: =B5/B6 -> 150 | C24: V | E24: Conduction loss total | F24: =B6*3*B26^2*(B15/1000) -> 7386.8883 | G24: W
A25: Fundamental VLL,rms per module | B25: =0.6123724357*B9*B24 -> 91.855865 | C25: V | E25: Switching energy scaled | F25: =(B12+B13)*(B24/B17)^B19*(B26/B18)^B20 -> 0.18608073 | G25: mJ/event
A26: Estimated AC phase current per module | B26: =B7*1000/(SQRT(3)*B25*B8)/B6 -> 248.10764 | C26: Arms | E26: Switching loss total | F26: =B30*(F25/1000)*(B16*1000) -> 2679.5625 | G26: W
A27: DC input current, ideal | B27: =B7*1000/B5 -> 250 | C27: A | E27: Total inverter loss | F27: =F24+F26+B21 -> 10066.451 | G27: W
A28: Suggested device blocking rating | B28: =B24*B10 -> 225 | C28: V | E28: Input power including losses | F28: =B7*1000+F27 -> 310066.45 | G28: W
A29: Suggested device current rating | B29: =B26*B11 -> 310.13455 | C29: A | E29: Efficiency | F29: =B7*1000/F28*100 -> 96.753454 | G29: %
A30: Total number of switches | B30: =6*B6 -> 48 | C30: - | E30: Loss share: conduction | F30: =IF(F27=0,0,F24/F27*100) -> 73.381258 | G30: %
A31: Module output power | B31: =B7/B6 -> 37.5 | C31: kW | E31: Loss share: switching | F31: =IF(F27=0,0,F26/F27*100) -> 26.618742 | G31: %
A34: Switching frequency sweep
A35: fsw (kHz) | B35: Conduction loss (W) | C35: Switching loss (W) | D35: Total loss (W) | E35: Efficiency (%)
A36: =B16/20*2 -> 30 | B36: =$F$24 -> 7386.8883 | C36: =$B$30*($F$25/1000)*(A36*1000) -> 267.95625 | D36: =B36+C36+$B$21 -> 7654.8445 | E36: =$B$7*1000/($B$7*1000+D36)*100 -> 97.511873
A37: =B16/20*2*2 -> 60 | B37: =$F$24 -> 7386.8883 | C37: =$B$30*($F$25/1000)*(A37*1000) -> 535.91251 | D37: =B37+C37+$B$21 -> 7922.8008 | E37: =$B$7*1000/($B$7*1000+D37)*100 -> 97.427017
A38: =B16/20*3*2 -> 90 | B38: =$F$24 -> 7386.8883 | C38: =$B$30*($F$25/1000)*(A38*1000) -> 803.86876 | D38: =B38+C38+$B$21 -> 8190.757 | E38: =$B$7*1000/($B$7*1000+D38)*100 -> 97.342309
A39: =B16/20*4*2 -> 120 | B39: =$F$24 -> 7386.8883 | C39: =$B$30*($F$25/1000)*(A39*1000) -> 1071.825 | D39: =B39+C39+$B$21 -> 8458.7133 | E39: =$B$7*1000/($B$7*1000+D39)*100 -> 97.257749
A40: =B16/20*5*2 -> 150 | B40: =$F$24 -> 7386.8883 | C40: =$B$30*($F$25/1000)*(A40*1000) -> 1339.7813 | D40: =B40+C40+$B$21 -> 8726.6695 | E40: =$B$7*1000/($B$7*1000+D40)*100 -> 97.173335
A41: =B16/20*6*2 -> 180 | B41: =$F$24 -> 7386.8883 | C41: =$B$30*($F$25/1000)*(A41*1000) -> 1607.7375 | D41: =B41+C41+$B$21 -> 8994.6258 | E41: =$B$7*1000/($B$7*1000+D41)*100 -> 97.089067
A42: =B16/20*7*2 -> 210 | B42: =$F$24 -> 7386.8883 | C42: =$B$30*($F$25/1000)*(A42*1000) -> 1875.6938 | D42: =B42+C42+$B$21 -> 9262.5821 | E42: =$B$7*1000/($B$7*1000+D42)*100 -> 97.004946
A43: =B16/20*8*2 -> 240 | B43: =$F$24 -> 7386.8883 | C43: =$B$30*($F$25/1000)*(A43*1000) -> 2143.65 | D43: =B43+C43+$B$21 -> 9530.5383 | E43: =$B$7*1000/($B$7*1000+D43)*100 -> 96.92097
...

Sheet Sensitivity
A1: Sensitivity: Efficiency versus Number of Series Modules and Switching Frequency
A3: This sheet references the main input cells and sweeps N and fsw. Change base inputs on the calculator sheet.
A5: N \ fsw (kHz) | B5: 5 | C5: 10 | D5: 15 | E5: 20 | F5: 25 | G5: 30 | H5: 40
A6: 1 | B6: =_xludf.LET(Vdc,'SPB Loss Calculator'!$B$5,Pkw,'SPB Loss Calculator'!$B$7,pf,'SPB Loss Calculator'!$B$8,m,'SPB Loss Calculator'!$B$9,Rds,'SPB Loss Calculator'!$B$14/1000,Eon,'SPB Loss Calculator'!$B$12,Eoff,'SPB Loss Calculator'!$B$13,Vref,'SPB Loss Calculator'!$B$17,Iref,'SPB Loss Calculator'!$B$18,av,'SPB Loss Calculator'!$B$19,ai,'SPB Loss Calculator'!$B$20,fixed,'SPB Loss Calculator'!$B$21,N,$A6,fsw,B$5,Vmod,Vdc/N,Vll,0.6123724357*m*Vmod,Irms,Pkw*1000/(SQRT(3)*Vll*pf),Pcond,N*3*Irms^2*Rds,Esw,(Eon+Eoff)*(Vmod/Vref)^av*(Irms/Iref)^ai,Psw,6*N*(Esw/1000)*(fsw*1000),Pkw*1000/(Pkw*1000+Pcond+Psw+fixed)*100) -> #NAME? | C6: =_xludf.LET(Vdc,'SPB Loss Calculator'!$B$5,Pkw,'SPB Loss Calculator'!$B$7,pf,'SPB Loss Calculator'!$B$8,m,'SPB Loss Calculator'!$B$9,Rds,'SPB Loss Calculator'!$B$14/1000,Eon,'SPB Loss Calculator'!$B$12,Eoff,'SPB Loss Calculator'!$B$13,Vref,'SPB Loss Calculator'!$B$17,Iref,'SPB Loss Calculator'!$B$18,av,'SPB Loss Calculator'!$B$19,ai,'SPB Loss Calculator'!$B$20,fixed,'SPB Loss Calculator'!$B$21,N,$A6,fsw,C$5,Vmod,Vdc/N,Vll,0.6123724357*m*Vmod,Irms,Pkw*1000/(SQRT(3)*Vll*pf),Pcond,N*3*Irms^2*Rds,Esw,(Eon+Eoff)*(Vmod/Vref)^av*(Irms/Iref)^ai,Psw,6*N*(Esw/1000)*(fsw*1000),Pkw*1000/(Pkw*1000+Pcond+Psw+fixed)*100) -> #NAME? | D6: =_xludf.LET(Vdc,'SPB Loss Calculator'!$B$5,Pkw,'SPB Loss Calculator'!$B$7,pf,'SPB Loss Calculator'!$B$8,m,'SPB Loss Calculator'!$B$9,Rds,'SPB Loss Calculator'!$B$14/1000,Eon,'SPB Loss Calculator'!$B$12,Eoff,'SPB Loss Calculator'!$B$13,Vref,'SPB Loss Calculator'!$B$17,Iref,'SPB Loss Calculator'!$B$18,av,'SPB Loss Calculator'!$B$19,ai,'SPB Loss Calculator'!$B$20,fixed,'SPB Loss Calculator'!$B$21,N,$A6,fsw,D$5,Vmod,Vdc/N,Vll,0.6123724357*m*Vmod,Irms,Pkw*1000/(SQRT(3)*Vll*pf),Pcond,N*3*Irms^2*Rds,Esw,(Eon+Eoff)*(Vmod/Vref)^av*(Irms/Iref)^ai,Psw,6*N*(Esw/1000)*(fsw*1000),Pkw*1000/(Pkw*1000+Pcond+Psw+fixed)*100) -> #NAME? | E6: =_xludf.LET(Vdc,'SPB Loss Calculator'!$B$5,Pkw,'SPB Loss Calculator'!$B$7,pf,'SPB Loss Calculator'!$B$8,m,'SPB Loss Calculator'!$B$9,Rds,'SPB Loss Calculator'!$B$14/1000,Eon,'SPB Loss Calculator'!$B$12,Eoff,'SPB Loss Calculator'!$B$13,Vref,'SPB Loss Calculator'!$B$17,Iref,'SPB Loss Calculator'!$B$18,av,'SPB Loss Calculator'!$B$19,ai,'SPB Loss Calculator'!$B$20,fixed,'SPB Loss Calculator'!$B$21,N,$A6,fsw,E$5,Vmod,Vdc/N,Vll,0.6123724357*m*Vmod,Irms,Pkw*1000/(SQRT(3)*Vll*pf),Pcond,N*3*Irms^2*Rds,Esw,(Eon+Eoff)*(Vmod/Vref)^av*(Irms/Iref)^ai,Psw,6*N*(Esw/1000)*(fsw*1000),Pkw*1000/(Pkw*1000+Pcond+Psw+fixed)*100) -> #NAME? | F6: =_xludf.LET(Vdc,'SPB Loss Calculator'!$B$5,Pkw,'SPB Loss Calculator'!$B$7,pf,'SPB Loss Calculator'!$B$8,m,'SPB Loss Calculator'!$B$9,Rds,'SPB Loss Calculator'!$B$14/1000,Eon,'SPB Loss Calculator'!$B$12,Eoff,'SPB Loss Calculator'!$B$13,Vref,'SPB Loss Calculator'!$B$17,Iref,'SPB Loss Calculator'!$B$18,av,'SPB Loss Calculator'!$B$19,ai,'SPB Loss Calculator'!$B$20,fixed,'SPB Loss Calculator'!$B$21,N,$A6,fsw,F$5,Vmod,Vdc/N,Vll,0.6123724357*m*Vmod,Irms,Pkw*1000/(SQRT(3)*Vll*pf),Pcond,N*3*Irms^2*Rds,Esw,(Eon+Eoff)*(Vmod/Vref)^av*(Irms/Iref)^ai,Psw,6*N*(Esw/1000)*(fsw*1000),Pkw*1000/(Pkw*1000+Pcond+Psw+fixed)*100) -> #NAME? | G6: =_xludf.LET(Vdc,'SPB Loss Calculator'!$B$5,Pkw,'SPB Loss Calculator'!$B$7,pf,'SPB Loss Calculator'!$B$8,m,'SPB Loss Calculator'!$B$9,Rds,'SPB Loss Calculator'!$B$14/1000,Eon,'SPB Loss Calculator'!$B$12,Eoff,'SPB Loss Calculator'!$B$13,Vref,'SPB Loss Calculator'!$B$17,Iref,'SPB Loss Calculator'!$B$18,av,'SPB Loss Calculator'!$B$19,ai,'SPB Loss Calculator'!$B$20,fixed,'SPB Loss Calculator'!$B$21,N,$A6,fsw,G$5,Vmod,Vdc/N,Vll,0.6123724357*m*Vmod,Irms,Pkw*1000/(SQRT(3)*Vll*pf),Pcond,N*3*Irms^2*Rds,Esw,(Eon+Eoff)*(Vmod/Vref)^av*(Irms/Iref)^ai,Psw,6*N*(Esw/1000)*(fsw*1000),Pkw*1000/(Pkw*1000+Pcond+Psw+fixed)*100) -> #NAME? | H6: =_xludf.LET(Vdc,'SPB Loss Calculator'!$B$5,Pkw,'SPB Loss Calculator'!$B$7,pf,'SPB Loss Calculator'!$B$8,m,'SPB Loss Calculator'!$B$9,Rds,'SPB Loss Calculator'!$B$14/1000,Eon,'SPB Loss Calculator'!$B$12,Eoff,'SPB Loss Calculator'!$B$13,Vref,'SPB Loss Calculator'!$B$17,Iref,'SPB Loss Calculator'!$B$18,av,'SPB Loss Calculator'!$B$19,ai,'SPB Loss Calculator'!$B$20,fixed,'SPB Loss Calculator'!$B$21,N,$A6,fsw,H$5,Vmod,Vdc/N,Vll,0.6123724357*m*Vmod,Irms,Pkw*1000/(SQRT(3)*Vll*pf),Pcond,N*3*Irms^2*Rds,Esw,(Eon+Eoff)*(Vmod/Vref)^av*(Irms/Iref)^ai,Psw,6*N*(Esw/1000)*(fsw*1000),Pkw*1000/(Pkw*1000+Pcond+Psw+fixed)*100) -> #NAME?
A7: 2 | B7: =_xludf.LET(Vdc,'SPB Loss Calculator'!$B$5,Pkw,'SPB Loss Calculator'!$B$7,pf,'SPB Loss Calculator'!$B$8,m,'SPB Loss Calculator'!$B$9,Rds,'SPB Loss Calculator'!$B$14/1000,Eon,'SPB Loss Calculator'!$B$12,Eoff,'SPB Loss Calculator'!$B$13,Vref,'SPB Loss Calculator'!$B$17,Iref,'SPB Loss Calculator'!$B$18,av,'SPB Loss Calculator'!$B$19,ai,'SPB Loss Calculator'!$B$20,fixed,'SPB Loss Calculator'!$B$21,N,$A7,fsw,B$5,Vmod,Vdc/N,Vll,0.6123724357*m*Vmod,Irms,Pkw*1000/(SQRT(3)*Vll*pf),Pcond,N*3*Irms^2*Rds,Esw,(Eon+Eoff)*(Vmod/Vref)^av*(Irms/Iref)^ai,Psw,6*N*(Esw/1000)*(fsw*1000),Pkw*1000/(Pkw*1000+Pcond+Psw+fixed)*100) -> #NAME? | C7: =_xludf.LET(Vdc,'SPB Loss Calculator'!$B$5,Pkw,'SPB Loss Calculator'!$B$7,pf,'SPB Loss Calculator'!$B$8,m,'SPB Loss Calculator'!$B$9,Rds,'SPB Loss Calculator'!$B$14/1000,Eon,'SPB Loss Calculator'!$B$12,Eoff,'SPB Loss Calculator'!$B$13,Vref,'SPB Loss Calculator'!$B$17,Iref,'SPB Loss Calculator'!$B$18,av,'SPB Loss Calculator'!$B$19,ai,'SPB Loss Calculator'!$B$20,fixed,'SPB Loss Calculator'!$B$21,N,$A7,fsw,C$5,Vmod,Vdc/N,Vll,0.6123724357*m*Vmod,Irms,Pkw*1000/(SQRT(3)*Vll*pf),Pcond,N*3*Irms^2*Rds,Esw,(Eon+Eoff)*(Vmod/Vref)^av*(Irms/Iref)^ai,Psw,6*N*(Esw/1000)*(fsw*1000),Pkw*1000/(Pkw*1000+Pcond+Psw+fixed)*100) -> #NAME? | D7: =_xludf.LET(Vdc,'SPB Loss Calculator'!$B$5,Pkw,'SPB Loss Calculator'!$B$7,pf,'SPB Loss Calculator'!$B$8,m,'SPB Loss Calculator'!$B$9,Rds,'SPB Loss Calculator'!$B$14/1000,Eon,'SPB Loss Calculator'!$B$12,Eoff,'SPB Loss Calculator'!$B$13,Vref,'SPB Loss Calculator'!$B$17,Iref,'SPB Loss Calculator'!$B$18,av,'SPB Loss Calculator'!$B$19,ai,'SPB Loss Calculator'!$B$20,fixed,'SPB Loss Calculator'!$B$21,N,$A7,fsw,D$5,Vmod,Vdc/N,Vll,0.6123724357*m*Vmod,Irms,Pkw*1000/(SQRT(3)*Vll*pf),Pcond,N*3*Irms^2*Rds,Esw,(Eon+Eoff)*(Vmod/Vref)^av*(Irms/Iref)^ai,Psw,6*N*(Esw/1000)*(fsw*1000),Pkw*1000/(Pkw*1000+Pcond+Psw+fixed)*100) -> #NAME? | E7: =_xludf.LET(Vdc,'SPB Loss Calculator'!$B$5,Pkw,'SPB Loss Calculator'!$B$7,pf,'SPB Loss Calculator'!$B$8,m,'SPB Loss Calculator'!$B$9,Rds,'SPB Loss Calculator'!$B$14/1000,Eon,'SPB Loss Calculator'!$B$12,Eoff,'SPB Loss Calculator'!$B$13,Vref,'SPB Loss Calculator'!$B$17,Iref,'SPB Loss Calculator'!$B$18,av,'SPB Loss Calculator'!$B$19,ai,'SPB Loss Calculator'!$B$20,fixed,'SPB Loss Calculator'!$B$21,N,$A7,fsw,E$5,Vmod,Vdc/N,Vll,0.6123724357*m*Vmod,Irms,Pkw*1000/(SQRT(3)*Vll*pf),Pcond,N*3*Irms^2*Rds,Esw,(Eon+Eoff)*(Vmod/Vref)^av*(Irms/Iref)^ai,Psw,6*N*(Esw/1000)*(fsw*1000),Pkw*1000/(Pkw*1000+Pcond+Psw+fixed)*100) -> #NAME? | F7: =_xludf.LET(Vdc,'SPB Loss Calculator'!$B$5,Pkw,'SPB Loss Calculator'!$B$7,pf,'SPB Loss Calculator'!$B$8,m,'SPB Loss Calculator'!$B$9,Rds,'SPB Loss Calculator'!$B$14/1000,Eon,'SPB Loss Calculator'!$B$12,Eoff,'SPB Loss Calculator'!$B$13,Vref,'SPB Loss Calculator'!$B$17,Iref,'SPB Loss Calculator'!$B$18,av,'SPB Loss Calculator'!$B$19,ai,'SPB Loss Calculator'!$B$20,fixed,'SPB Loss Calculator'!$B$21,N,$A7,fsw,F$5,Vmod,Vdc/N,Vll,0.6123724357*m*Vmod,Irms,Pkw*1000/(SQRT(3)*Vll*pf),Pcond,N*3*Irms^2*Rds,Esw,(Eon+Eoff)*(Vmod/Vref)^av*(Irms/Iref)^ai,Psw,6*N*(Esw/1000)*(fsw*1000),Pkw*1000/(Pkw*1000+Pcond+Psw+fixed)*100) -> #NAME? | G7: =_xludf.LET(Vdc,'SPB Loss Calculator'!$B$5,Pkw,'SPB Loss Calculator'!$B$7,pf,'SPB Loss Calculator'!$B$8,m,'SPB Loss Calculator'!$B$9,Rds,'SPB Loss Calculator'!$B$14/1000,Eon,'SPB Loss Calculator'!$B$12,Eoff,'SPB Loss Calculator'!$B$13,Vref,'SPB Loss Calculator'!$B$17,Iref,'SPB Loss Calculator'!$B$18,av,'SPB Loss Calculator'!$B$19,ai,'SPB Loss Calculator'!$B$20,fixed,'SPB Loss Calculator'!$B$21,N,$A7,fsw,G$5,Vmod,Vdc/N,Vll,0.6123724357*m*Vmod,Irms,Pkw*1000/(SQRT(3)*Vll*pf),Pcond,N*3*Irms^2*Rds,Esw,(Eon+Eoff)*(Vmod/Vref)^av*(Irms/Iref)^ai,Psw,6*N*(Esw/1000)*(fsw*1000),Pkw*1000/(Pkw*1000+Pcond+Psw+fixed)*100) -> #NAME? | H7: =_xludf.LET(Vdc,'SPB Loss Calculator'!$B$5,Pkw,'SPB Loss Calculator'!$B$7,pf,'SPB Loss Calculator'!$B$8,m,'SPB Loss Calculator'!$B$9,Rds,'SPB Loss Calculator'!$B$14/1000,Eon,'SPB Loss Calculator'!$B$12,Eoff,'SPB Loss Calculator'!$B$13,Vref,'SPB Loss Calculator'!$B$17,Iref,'SPB Loss Calculator'!$B$18,av,'SPB Loss Calculator'!$B$19,ai,'SPB Loss Calculator'!$B$20,fixed,'SPB Loss Calculator'!$B$21,N,$A7,fsw,H$5,Vmod,Vdc/N,Vll,0.6123724357*m*Vmod,Irms,Pkw*1000/(SQRT(3)*Vll*pf),Pcond,N*3*Irms^2*Rds,Esw,(Eon+Eoff)*(Vmod/Vref)^av*(Irms/Iref)^ai,Psw,6*N*(Esw/1000)*(fsw*1000),Pkw*1000/(Pkw*1000+Pcond+Psw+fixed)*100) -> #NAME?
A8: 3 | B8: =_xludf.LET(Vdc,'SPB Loss Calculator'!$B$5,Pkw,'SPB Loss Calculator'!$B$7,pf,'SPB Loss Calculator'!$B$8,m,'SPB Loss Calculator'!$B$9,Rds,'SPB Loss Calculator'!$B$14/1000,Eon,'SPB Loss Calculator'!$B$12,Eoff,'SPB Loss Calculator'!$B$13,Vref,'SPB Loss Calculator'!$B$17,Iref,'SPB Loss Calculator'!$B$18,av,'SPB Loss Calculator'!$B$19,ai,'SPB Loss Calculator'!$B$20,fixed,'SPB Loss Calculator'!$B$21,N,$A8,fsw,B$5,Vmod,Vdc/N,Vll,0.6123724357*m*Vmod,Irms,Pkw*1000/(SQRT(3)*Vll*pf),Pcond,N*3*Irms^2*Rds,Esw,(Eon+Eoff)*(Vmod/Vref)^av*(Irms/Iref)^ai,Psw,6*N*(Esw/1000)*(fsw*1000),Pkw*1000/(Pkw*1000+Pcond+Psw+fixed)*100) -> #NAME? | C8: =_xludf.LET(Vdc,'SPB Loss Calculator'!$B$5,Pkw,'SPB Loss Calculator'!$B$7,pf,'SPB Loss Calculator'!$B$8,m,'SPB Loss Calculator'!$B$9,Rds,'SPB Loss Calculator'!$B$14/1000,Eon,'SPB Loss Calculator'!$B$12,Eoff,'SPB Loss Calculator'!$B$13,Vref,'SPB Loss Calculator'!$B$17,Iref,'SPB Loss Calculator'!$B$18,av,'SPB Loss Calculator'!$B$19,ai,'SPB Loss Calculator'!$B$20,fixed,'SPB Loss Calculator'!$B$21,N,$A8,fsw,C$5,Vmod,Vdc/N,Vll,0.6123724357*m*Vmod,Irms,Pkw*1000/(SQRT(3)*Vll*pf),Pcond,N*3*Irms^2*Rds,Esw,(Eon+Eoff)*(Vmod/Vref)^av*(Irms/Iref)^ai,Psw,6*N*(Esw/1000)*(fsw*1000),Pkw*1000/(Pkw*1000+Pcond+Psw+fixed)*100) -> #NAME? | D8: =_xludf.LET(Vdc,'SPB Loss Calculator'!$B$5,Pkw,'SPB Loss Calculator'!$B$7,pf,'SPB Loss Calculator'!$B$8,m,'SPB Loss Calculator'!$B$9,Rds,'SPB Loss Calculator'!$B$14/1000,Eon,'SPB Loss Calculator'!$B$12,Eoff,'SPB Loss Calculator'!$B$13,Vref,'SPB Loss Calculator'!$B$17,Iref,'SPB Loss Calculator'!$B$18,av,'SPB Loss Calculator'!$B$19,ai,'SPB Loss Calculator'!$B$20,fixed,'SPB Loss Calculator'!$B$21,N,$A8,fsw,D$5,Vmod,Vdc/N,Vll,0.6123724357*m*Vmod,Irms,Pkw*1000/(SQRT(3)*Vll*pf),Pcond,N*3*Irms^2*Rds,Esw,(Eon+Eoff)*(Vmod/Vref)^av*(Irms/Iref)^ai,Psw,6*N*(Esw/1000)*(fsw*1000),Pkw*1000/(Pkw*1000+Pcond+Psw+fixed)*100) -> #NAME? | E8: =_xludf.LET(Vdc,'SPB Loss Calculator'!$B$5,Pkw,'SPB Loss Calculator'!$B$7,pf,'SPB Loss Calculator'!$B$8,m,'SPB Loss Calculator'!$B$9,Rds,'SPB Loss Calculator'!$B$14/1000,Eon,'SPB Loss Calculator'!$B$12,Eoff,'SPB Loss Calculator'!$B$13,Vref,'SPB Loss Calculator'!$B$17,Iref,'SPB Loss Calculator'!$B$18,av,'SPB Loss Calculator'!$B$19,ai,'SPB Loss Calculator'!$B$20,fixed,'SPB Loss Calculator'!$B$21,N,$A8,fsw,E$5,Vmod,Vdc/N,Vll,0.6123724357*m*Vmod,Irms,Pkw*1000/(SQRT(3)*Vll*pf),Pcond,N*3*Irms^2*Rds,Esw,(Eon+Eoff)*(Vmod/Vref)^av*(Irms/Iref)^ai,Psw,6*N*(Esw/1000)*(fsw*1000),Pkw*1000/(Pkw*1000+Pcond+Psw+fixed)*100) -> #NAME? | F8: =_xludf.LET(Vdc,'SPB Loss Calculator'!$B$5,Pkw,'SPB Loss Calculator'!$B$7,pf,'SPB Loss Calculator'!$B$8,m,'SPB Loss Calculator'!$B$9,Rds,'SPB Loss Calculator'!$B$14/1000,Eon,'SPB Loss Calculator'!$B$12,Eoff,'SPB Loss Calculator'!$B$13,Vref,'SPB Loss Calculator'!$B$17,Iref,'SPB Loss Calculator'!$B$18,av,'SPB Loss Calculator'!$B$19,ai,'SPB Loss Calculator'!$B$20,fixed,'SPB Loss Calculator'!$B$21,N,$A8,fsw,F$5,Vmod,Vdc/N,Vll,0.6123724357*m*Vmod,Irms,Pkw*1000/(SQRT(3)*Vll*pf),Pcond,N*3*Irms^2*Rds,Esw,(Eon+Eoff)*(Vmod/Vref)^av*(Irms/Iref)^ai,Psw,6*N*(Esw/1000)*(fsw*1000),Pkw*1000/(Pkw*1000+Pcond+Psw+fixed)*100) -> #NAME? | G8: =_xludf.LET(Vdc,'SPB Loss Calculator'!$B$5,Pkw,'SPB Loss Calculator'!$B$7,pf,'SPB Loss Calculator'!$B$8,m,'SPB Loss Calculator'!$B$9,Rds,'SPB Loss Calculator'!$B$14/1000,Eon,'SPB Loss Calculator'!$B$12,Eoff,'SPB Loss Calculator'!$B$13,Vref,'SPB Loss Calculator'!$B$17,Iref,'SPB Loss Calculator'!$B$18,av,'SPB Loss Calculator'!$B$19,ai,'SPB Loss Calculator'!$B$20,fixed,'SPB Loss Calculator'!$B$21,N,$A8,fsw,G$5,Vmod,Vdc/N,Vll,0.6123724357*m*Vmod,Irms,Pkw*1000/(SQRT(3)*Vll*pf),Pcond,N*3*Irms^2*Rds,Esw,(Eon+Eoff)*(Vmod/Vref)^av*(Irms/Iref)^ai,Psw,6*N*(Esw/1000)*(fsw*1000),Pkw*1000/(Pkw*1000+Pcond+Psw+fixed)*100) -> #NAME? | H8: =_xludf.LET(Vdc,'SPB Loss Calculator'!$B$5,Pkw,'SPB Loss Calculator'!$B$7,pf,'SPB Loss Calculator'!$B$8,m,'SPB Loss Calculator'!$B$9,Rds,'SPB Loss Calculator'!$B$14/1000,Eon,'SPB Loss Calculator'!$B$12,Eoff,'SPB Loss Calculator'!$B$13,Vref,'SPB Loss Calculator'!$B$17,Iref,'SPB Loss Calculator'!$B$18,av,'SPB Loss Calculator'!$B$19,ai,'SPB Loss Calculator'!$B$20,fixed,'SPB Loss Calculator'!$B$21,N,$A8,fsw,H$5,Vmod,Vdc/N,Vll,0.6123724357*m*Vmod,Irms,Pkw*1000/(SQRT(3)*Vll*pf),Pcond,N*3*Irms^2*Rds,Esw,(Eon+Eoff)*(Vmod/Vref)^av*(Irms/Iref)^ai,Psw,6*N*(Esw/1000)*(fsw*1000),Pkw*1000/(Pkw*1000+Pcond+Psw+fixed)*100) -> #NAME?
A9: 4 | B9: =_xludf.LET(Vdc,'SPB Loss Calculator'!$B$5,Pkw,'SPB Loss Calculator'!$B$7,pf,'SPB Loss Calculator'!$B$8,m,'SPB Loss Calculator'!$B$9,Rds,'SPB Loss Calculator'!$B$14/1000,Eon,'SPB Loss Calculator'!$B$12,Eoff,'SPB Loss Calculator'!$B$13,Vref,'SPB Loss Calculator'!$B$17,Iref,'SPB Loss Calculator'!$B$18,av,'SPB Loss Calculator'!$B$19,ai,'SPB Loss Calculator'!$B$20,fixed,'SPB Loss Calculator'!$B$21,N,$A9,fsw,B$5,Vmod,Vdc/N,Vll,0.6123724357*m*Vmod,Irms,Pkw*1000/(SQRT(3)*Vll*pf),Pcond,N*3*Irms^2*Rds,Esw,(Eon+Eoff)*(Vmod/Vref)^av*(Irms/Iref)^ai,Psw,6*N*(Esw/1000)*(fsw*1000),Pkw*1000/(Pkw*1000+Pcond+Psw+fixed)*100) -> #NAME? | C9: =_xludf.LET(Vdc,'SPB Loss Calculator'!$B$5,Pkw,'SPB Loss Calculator'!$B$7,pf,'SPB Loss Calculator'!$B$8,m,'SPB Loss Calculator'!$B$9,Rds,'SPB Loss Calculator'!$B$14/1000,Eon,'SPB Loss Calculator'!$B$12,Eoff,'SPB Loss Calculator'!$B$13,Vref,'SPB Loss Calculator'!$B$17,Iref,'SPB Loss Calculator'!$B$18,av,'SPB Loss Calculator'!$B$19,ai,'SPB Loss Calculator'!$B$20,fixed,'SPB Loss Calculator'!$B$21,N,$A9,fsw,C$5,Vmod,Vdc/N,Vll,0.6123724357*m*Vmod,Irms,Pkw*1000/(SQRT(3)*Vll*pf),Pcond,N*3*Irms^2*Rds,Esw,(Eon+Eoff)*(Vmod/Vref)^av*(Irms/Iref)^ai,Psw,6*N*(Esw/1000)*(fsw*1000),Pkw*1000/(Pkw*1000+Pcond+Psw+fixed)*100) -> #NAME? | D9: =_xludf.LET(Vdc,'SPB Loss Calculator'!$B$5,Pkw,'SPB Loss Calculator'!$B$7,pf,'SPB Loss Calculator'!$B$8,m,'SPB Loss Calculator'!$B$9,Rds,'SPB Loss Calculator'!$B$14/1000,Eon,'SPB Loss Calculator'!$B$12,Eoff,'SPB Loss Calculator'!$B$13,Vref,'SPB Loss Calculator'!$B$17,Iref,'SPB Loss Calculator'!$B$18,av,'SPB Loss Calculator'!$B$19,ai,'SPB Loss Calculator'!$B$20,fixed,'SPB Loss Calculator'!$B$21,N,$A9,fsw,D$5,Vmod,Vdc/N,Vll,0.6123724357*m*Vmod,Irms,Pkw*1000/(SQRT(3)*Vll*pf),Pcond,N*3*Irms^2*Rds,Esw,(Eon+Eoff)*(Vmod/Vref)^av*(Irms/Iref)^ai,Psw,6*N*(Esw/1000)*(fsw*1000),Pkw*1000/(Pkw*1000+Pcond+Psw+fixed)*100) -> #NAME? | E9: =_xludf.LET(Vdc,'SPB Loss Calculator'!$B$5,Pkw,'SPB Loss Calculator'!$B$7,pf,'SPB Loss Calculator'!$B$8,m,'SPB Loss Calculator'!$B$9,Rds,'SPB Loss Calculator'!$B$14/1000,Eon,'SPB Loss Calculator'!$B$12,Eoff,'SPB Loss Calculator'!$B$13,Vref,'SPB Loss Calculator'!$B$17,Iref,'SPB Loss Calculator'!$B$18,av,'SPB Loss Calculator'!$B$19,ai,'SPB Loss Calculator'!$B$20,fixed,'SPB Loss Calculator'!$B$21,N,$A9,fsw,E$5,Vmod,Vdc/N,Vll,0.6123724357*m*Vmod,Irms,Pkw*1000/(SQRT(3)*Vll*pf),Pcond,N*3*Irms^2*Rds,Esw,(Eon+Eoff)*(Vmod/Vref)^av*(Irms/Iref)^ai,Psw,6*N*(Esw/1000)*(fsw*1000),Pkw*1000/(Pkw*1000+Pcond+Psw+fixed)*100) -> #NAME? | F9: =_xludf.LET(Vdc,'SPB Loss Calculator'!$B$5,Pkw,'SPB Loss Calculator'!$B$7,pf,'SPB Loss Calculator'!$B$8,m,'SPB Loss Calculator'!$B$9,Rds,'SPB Loss Calculator'!$B$14/1000,Eon,'SPB Loss Calculator'!$B$12,Eoff,'SPB Loss Calculator'!$B$13,Vref,'SPB Loss Calculator'!$B$17,Iref,'SPB Loss Calculator'!$B$18,av,'SPB Loss Calculator'!$B$19,ai,'SPB Loss Calculator'!$B$20,fixed,'SPB Loss Calculator'!$B$21,N,$A9,fsw,F$5,Vmod,Vdc/N,Vll,0.6123724357*m*Vmod,Irms,Pkw*1000/(SQRT(3)*Vll*pf),Pcond,N*3*Irms^2*Rds,Esw,(Eon+Eoff)*(Vmod/Vref)^av*(Irms/Iref)^ai,Psw,6*N*(Esw/1000)*(fsw*1000),Pkw*1000/(Pkw*1000+Pcond+Psw+fixed)*100) -> #NAME? | G9: =_xludf.LET(Vdc,'SPB Loss Calculator'!$B$5,Pkw,'SPB Loss Calculator'!$B$7,pf,'SPB Loss Calculator'!$B$8,m,'SPB Loss Calculator'!$B$9,Rds,'SPB Loss Calculator'!$B$14/1000,Eon,'SPB Loss Calculator'!$B$12,Eoff,'SPB Loss Calculator'!$B$13,Vref,'SPB Loss Calculator'!$B$17,Iref,'SPB Loss Calculator'!$B$18,av,'SPB Loss Calculator'!$B$19,ai,'SPB Loss Calculator'!$B$20,fixed,'SPB Loss Calculator'!$B$21,N,$A9,fsw,G$5,Vmod,Vdc/N,Vll,0.6123724357*m*Vmod,Irms,Pkw*1000/(SQRT(3)*Vll*pf),Pcond,N*3*Irms^2*Rds,Esw,(Eon+Eoff)*(Vmod/Vref)^av*(Irms/Iref)^ai,Psw,6*N*(Esw/1000)*(fsw*1000),Pkw*1000/(Pkw*1000+Pcond+Psw+fixed)*100) -> #NAME? | H9: =_xludf.LET(Vdc,'SPB Loss Calculator'!$B$5,Pkw,'SPB Loss Calculator'!$B$7,pf,'SPB Loss Calculator'!$B$8,m,'SPB Loss Calculator'!$B$9,Rds,'SPB Loss Calculator'!$B$14/1000,Eon,'SPB Loss Calculator'!$B$12,Eoff,'SPB Loss Calculator'!$B$13,Vref,'SPB Loss Calculator'!$B$17,Iref,'SPB Loss Calculator'!$B$18,av,'SPB Loss Calculator'!$B$19,ai,'SPB Loss Calculator'!$B$20,fixed,'SPB Loss Calculator'!$B$21,N,$A9,fsw,H$5,Vmod,Vdc/N,Vll,0.6123724357*m*Vmod,Irms,Pkw*1000/(SQRT(3)*Vll*pf),Pcond,N*3*Irms^2*Rds,Esw,(Eon+Eoff)*(Vmod/Vref)^av*(Irms/Iref)^ai,Psw,6*N*(Esw/1000)*(fsw*1000),Pkw*1000/(Pkw*1000+Pcond+Psw+fixed)*100) -> #NAME?
A10: 5 | B10: =_xludf.LET(Vdc,'SPB Loss Calculator'!$B$5,Pkw,'SPB Loss Calculator'!$B$7,pf,'SPB Loss Calculator'!$B$8,m,'SPB Loss Calculator'!$B$9,Rds,'SPB Loss Calculator'!$B$14/1000,Eon,'SPB Loss Calculator'!$B$12,Eoff,'SPB Loss Calculator'!$B$13,Vref,'SPB Loss Calculator'!$B$17,Iref,'SPB Loss Calculator'!$B$18,av,'SPB Loss Calculator'!$B$19,ai,'SPB Loss Calculator'!$B$20,fixed,'SPB Loss Calculator'!$B$21,N,$A10,fsw,B$5,Vmod,Vdc/N,Vll,0.6123724357*m*Vmod,Irms,Pkw*1000/(SQRT(3)*Vll*pf),Pcond,N*3*Irms^2*Rds,Esw,(Eon+Eoff)*(Vmod/Vref)^av*(Irms/Iref)^ai,Psw,6*N*(Esw/1000)*(fsw*1000),Pkw*1000/(Pkw*1000+Pcond+Psw+fixed)*100) -> #NAME? | C10: =_xludf.LET(Vdc,'SPB Loss Calculator'!$B$5,Pkw,'SPB Loss Calculator'!$B$7,pf,'SPB Loss Calculator'!$B$8,m,'SPB Loss Calculator'!$B$9,Rds,'SPB Loss Calculator'!$B$14/1000,Eon,'SPB Loss Calculator'!$B$12,Eoff,'SPB Loss Calculator'!$B$13,Vref,'SPB Loss Calculator'!$B$17,Iref,'SPB Loss Calculator'!$B$18,av,'SPB Loss Calculator'!$B$19,ai,'SPB Loss Calculator'!$B$20,fixed,'SPB Loss Calculator'!$B$21,N,$A10,fsw,C$5,Vmod,Vdc/N,Vll,0.6123724357*m*Vmod,Irms,Pkw*1000/(SQRT(3)*Vll*pf),Pcond,N*3*Irms^2*Rds,Esw,(Eon+Eoff)*(Vmod/Vref)^av*(Irms/Iref)^ai,Psw,6*N*(Esw/1000)*(fsw*1000),Pkw*1000/(Pkw*1000+Pcond+Psw+fixed)*100) -> #NAME? | D10: =_xludf.LET(Vdc,'SPB Loss Calculator'!$B$5,Pkw,'SPB Loss Calculator'!$B$7,pf,'SPB Loss Calculator'!$B$8,m,'SPB Loss Calculator'!$B$9,Rds,'SPB Loss Calculator'!$B$14/1000,Eon,'SPB Loss Calculator'!$B$12,Eoff,'SPB Loss Calculator'!$B$13,Vref,'SPB Loss Calculator'!$B$17,Iref,'SPB Loss Calculator'!$B$18,av,'SPB Loss Calculator'!$B$19,ai,'SPB Loss Calculator'!$B$20,fixed,'SPB Loss Calculator'!$B$21,N,$A10,fsw,D$5,Vmod,Vdc/N,Vll,0.6123724357*m*Vmod,Irms,Pkw*1000/(SQRT(3)*Vll*pf),Pcond,N*3*Irms^2*Rds,Esw,(Eon+Eoff)*(Vmod/Vref)^av*(Irms/Iref)^ai,Psw,6*N*(Esw/1000)*(fsw*1000),Pkw*1000/(Pkw*1000+Pcond+Psw+fixed)*100) -> #NAME? | E10: =_xludf.LET(Vdc,'SPB Loss Calculator'!$B$5,Pkw,'SPB Loss Calculator'!$B$7,pf,'SPB Loss Calculator'!$B$8,m,'SPB Loss Calculator'!$B$9,Rds,'SPB Loss Calculator'!$B$14/1000,Eon,'SPB Loss Calculator'!$B$12,Eoff,'SPB Loss Calculator'!$B$13,Vref,'SPB Loss Calculator'!$B$17,Iref,'SPB Loss Calculator'!$B$18,av,'SPB Loss Calculator'!$B$19,ai,'SPB Loss Calculator'!$B$20,fixed,'SPB Loss Calculator'!$B$21,N,$A10,fsw,E$5,Vmod,Vdc/N,Vll,0.6123724357*m*Vmod,Irms,Pkw*1000/(SQRT(3)*Vll*pf),Pcond,N*3*Irms^2*Rds,Esw,(Eon+Eoff)*(Vmod/Vref)^av*(Irms/Iref)^ai,Psw,6*N*(Esw/1000)*(fsw*1000),Pkw*1000/(Pkw*1000+Pcond+Psw+fixed)*100) -> #NAME? | F10: =_xludf.LET(Vdc,'SPB Loss Calculator'!$B$5,Pkw,'SPB Loss Calculator'!$B$7,pf,'SPB Loss Calculator'!$B$8,m,'SPB Loss Calculator'!$B$9,Rds,'SPB Loss Calculator'!$B$14/1000,Eon,'SPB Loss Calculator'!$B$12,Eoff,'SPB Loss Calculator'!$B$13,Vref,'SPB Loss Calculator'!$B$17,Iref,'SPB Loss Calculator'!$B$18,av,'SPB Loss Calculator'!$B$19,ai,'SPB Loss Calculator'!$B$20,fixed,'SPB Loss Calculator'!$B$21,N,$A10,fsw,F$5,Vmod,Vdc/N,Vll,0.6123724357*m*Vmod,Irms,Pkw*1000/(SQRT(3)*Vll*pf),Pcond,N*3*Irms^2*Rds,Esw,(Eon+Eoff)*(Vmod/Vref)^av*(Irms/Iref)^ai,Psw,6*N*(Esw/1000)*(fsw*1000),Pkw*1000/(Pkw*1000+Pcond+Psw+fixed)*100) -> #NAME? | G10: =_xludf.LET(Vdc,'SPB Loss Calculator'!$B$5,Pkw,'SPB Loss Calculator'!$B$7,pf,'SPB Loss Calculator'!$B$8,m,'SPB Loss Calculator'!$B$9,Rds,'SPB Loss Calculator'!$B$14/1000,Eon,'SPB Loss Calculator'!$B$12,Eoff,'SPB Loss Calculator'!$B$13,Vref,'SPB Loss Calculator'!$B$17,Iref,'SPB Loss Calculator'!$B$18,av,'SPB Loss Calculator'!$B$19,ai,'SPB Loss Calculator'!$B$20,fixed,'SPB Loss Calculator'!$B$21,N,$A10,fsw,G$5,Vmod,Vdc/N,Vll,0.6123724357*m*Vmod,Irms,Pkw*1000/(SQRT(3)*Vll*pf),Pcond,N*3*Irms^2*Rds,Esw,(Eon+Eoff)*(Vmod/Vref)^av*(Irms/Iref)^ai,Psw,6*N*(Esw/1000)*(fsw*1000),Pkw*1000/(Pkw*1000+Pcond+Psw+fixed)*100) -> #NAME? | H10: =_xludf.LET(Vdc,'SPB Loss Calculator'!$B$5,Pkw,'SPB Loss Calculator'!$B$7,pf,'SPB Loss Calculator'!$B$8,m,'SPB Loss Calculator'!$B$9,Rds,'SPB Loss Calculator'!$B$14/1000,Eon,'SPB Loss Calculator'!$B$12,Eoff,'SPB Loss Calculator'!$B$13,Vref,'SPB Loss Calculator'!$B$17,Iref,'SPB Loss Calculator'!$B$18,av,'SPB Loss Calculator'!$B$19,ai,'SPB Loss Calculator'!$B$20,fixed,'SPB Loss Calculator'!$B$21,N,$A10,fsw,H$5,Vmod,Vdc/N,Vll,0.6123724357*m*Vmod,Irms,Pkw*1000/(SQRT(3)*Vll*pf),Pcond,N*3*Irms^2*Rds,Esw,(Eon+Eoff)*(Vmod/Vref)^av*(Irms/Iref)^ai,Psw,6*N*(Esw/1000)*(fsw*1000),Pkw*1000/(Pkw*1000+Pcond+Psw+fixed)*100) -> #NAME?
A11: 6 | B11: =_xludf.LET(Vdc,'SPB Loss Calculator'!$B$5,Pkw,'SPB Loss Calculator'!$B$7,pf,'SPB Loss Calculator'!$B$8,m,'SPB Loss Calculator'!$B$9,Rds,'SPB Loss Calculator'!$B$14/1000,Eon,'SPB Loss Calculator'!$B$12,Eoff,'SPB Loss Calculator'!$B$13,Vref,'SPB Loss Calculator'!$B$17,Iref,'SPB Loss Calculator'!$B$18,av,'SPB Loss Calculator'!$B$19,ai,'SPB Loss Calculator'!$B$20,fixed,'SPB Loss Calculator'!$B$21,N,$A11,fsw,B$5,Vmod,Vdc/N,Vll,0.6123724357*m*Vmod,Irms,Pkw*1000/(SQRT(3)*Vll*pf),Pcond,N*3*Irms^2*Rds,Esw,(Eon+Eoff)*(Vmod/Vref)^av*(Irms/Iref)^ai,Psw,6*N*(Esw/1000)*(fsw*1000),Pkw*1000/(Pkw*1000+Pcond+Psw+fixed)*100) -> #NAME? | C11: =_xludf.LET(Vdc,'SPB Loss Calculator'!$B$5,Pkw,'SPB Loss Calculator'!$B$7,pf,'SPB Loss Calculator'!$B$8,m,'SPB Loss Calculator'!$B$9,Rds,'SPB Loss Calculator'!$B$14/1000,Eon,'SPB Loss Calculator'!$B$12,Eoff,'SPB Loss Calculator'!$B$13,Vref,'SPB Loss Calculator'!$B$17,Iref,'SPB Loss Calculator'!$B$18,av,'SPB Loss Calculator'!$B$19,ai,'SPB Loss Calculator'!$B$20,fixed,'SPB Loss Calculator'!$B$21,N,$A11,fsw,C$5,Vmod,Vdc/N,Vll,0.6123724357*m*Vmod,Irms,Pkw*1000/(SQRT(3)*Vll*pf),Pcond,N*3*Irms^2*Rds,Esw,(Eon+Eoff)*(Vmod/Vref)^av*(Irms/Iref)^ai,Psw,6*N*(Esw/1000)*(fsw*1000),Pkw*1000/(Pkw*1000+Pcond+Psw+fixed)*100) -> #NAME? | D11: =_xludf.LET(Vdc,'SPB Loss Calculator'!$B$5,Pkw,'SPB Loss Calculator'!$B$7,pf,'SPB Loss Calculator'!$B$8,m,'SPB Loss Calculator'!$B$9,Rds,'SPB Loss Calculator'!$B$14/1000,Eon,'SPB Loss Calculator'!$B$12,Eoff,'SPB Loss Calculator'!$B$13,Vref,'SPB Loss Calculator'!$B$17,Iref,'SPB Loss Calculator'!$B$18,av,'SPB Loss Calculator'!$B$19,ai,'SPB Loss Calculator'!$B$20,fixed,'SPB Loss Calculator'!$B$21,N,$A11,fsw,D$5,Vmod,Vdc/N,Vll,0.6123724357*m*Vmod,Irms,Pkw*1000/(SQRT(3)*Vll*pf),Pcond,N*3*Irms^2*Rds,Esw,(Eon+Eoff)*(Vmod/Vref)^av*(Irms/Iref)^ai,Psw,6*N*(Esw/1000)*(fsw*1000),Pkw*1000/(Pkw*1000+Pcond+Psw+fixed)*100) -> #NAME? | E11: =_xludf.LET(Vdc,'SPB Loss Calculator'!$B$5,Pkw,'SPB Loss Calculator'!$B$7,pf,'SPB Loss Calculator'!$B$8,m,'SPB Loss Calculator'!$B$9,Rds,'SPB Loss Calculator'!$B$14/1000,Eon,'SPB Loss Calculator'!$B$12,Eoff,'SPB Loss Calculator'!$B$13,Vref,'SPB Loss Calculator'!$B$17,Iref,'SPB Loss Calculator'!$B$18,av,'SPB Loss Calculator'!$B$19,ai,'SPB Loss Calculator'!$B$20,fixed,'SPB Loss Calculator'!$B$21,N,$A11,fsw,E$5,Vmod,Vdc/N,Vll,0.6123724357*m*Vmod,Irms,Pkw*1000/(SQRT(3)*Vll*pf),Pcond,N*3*Irms^2*Rds,Esw,(Eon+Eoff)*(Vmod/Vref)^av*(Irms/Iref)^ai,Psw,6*N*(Esw/1000)*(fsw*1000),Pkw*1000/(Pkw*1000+Pcond+Psw+fixed)*100) -> #NAME? | F11: =_xludf.LET(Vdc,'SPB Loss Calculator'!$B$5,Pkw,'SPB Loss Calculator'!$B$7,pf,'SPB Loss Calculator'!$B$8,m,'SPB Loss Calculator'!$B$9,Rds,'SPB Loss Calculator'!$B$14/1000,Eon,'SPB Loss Calculator'!$B$12,Eoff,'SPB Loss Calculator'!$B$13,Vref,'SPB Loss Calculator'!$B$17,Iref,'SPB Loss Calculator'!$B$18,av,'SPB Loss Calculator'!$B$19,ai,'SPB Loss Calculator'!$B$20,fixed,'SPB Loss Calculator'!$B$21,N,$A11,fsw,F$5,Vmod,Vdc/N,Vll,0.6123724357*m*Vmod,Irms,Pkw*1000/(SQRT(3)*Vll*pf),Pcond,N*3*Irms^2*Rds,Esw,(Eon+Eoff)*(Vmod/Vref)^av*(Irms/Iref)^ai,Psw,6*N*(Esw/1000)*(fsw*1000),Pkw*1000/(Pkw*1000+Pcond+Psw+fixed)*100) -> #NAME? | G11: =_xludf.LET(Vdc,'SPB Loss Calculator'!$B$5,Pkw,'SPB Loss Calculator'!$B$7,pf,'SPB Loss Calculator'!$B$8,m,'SPB Loss Calculator'!$B$9,Rds,'SPB Loss Calculator'!$B$14/1000,Eon,'SPB Loss Calculator'!$B$12,Eoff,'SPB Loss Calculator'!$B$13,Vref,'SPB Loss Calculator'!$B$17,Iref,'SPB Loss Calculator'!$B$18,av,'SPB Loss Calculator'!$B$19,ai,'SPB Loss Calculator'!$B$20,fixed,'SPB Loss Calculator'!$B$21,N,$A11,fsw,G$5,Vmod,Vdc/N,Vll,0.6123724357*m*Vmod,Irms,Pkw*1000/(SQRT(3)*Vll*pf),Pcond,N*3*Irms^2*Rds,Esw,(Eon+Eoff)*(Vmod/Vref)^av*(Irms/Iref)^ai,Psw,6*N*(Esw/1000)*(fsw*1000),Pkw*1000/(Pkw*1000+Pcond+Psw+fixed)*100) -> #NAME? | H11: =_xludf.LET(Vdc,'SPB Loss Calculator'!$B$5,Pkw,'SPB Loss Calculator'!$B$7,pf,'SPB Loss Calculator'!$B$8,m,'SPB Loss Calculator'!$B$9,Rds,'SPB Loss Calculator'!$B$14/1000,Eon,'SPB Loss Calculator'!$B$12,Eoff,'SPB Loss Calculator'!$B$13,Vref,'SPB Loss Calculator'!$B$17,Iref,'SPB Loss Calculator'!$B$18,av,'SPB Loss Calculator'!$B$19,ai,'SPB Loss Calculator'!$B$20,fixed,'SPB Loss Calculator'!$B$21,N,$A11,fsw,H$5,Vmod,Vdc/N,Vll,0.6123724357*m*Vmod,Irms,Pkw*1000/(SQRT(3)*Vll*pf),Pcond,N*3*Irms^2*Rds,Esw,(Eon+Eoff)*(Vmod/Vref)^av*(Irms/Iref)^ai,Psw,6*N*(Esw/1000)*(fsw*1000),Pkw*1000/(Pkw*1000+Pcond+Psw+fixed)*100) -> #NAME?
A12: 7 | B12: =_xludf.LET(Vdc,'SPB Loss Calculator'!$B$5,Pkw,'SPB Loss Calculator'!$B$7,pf,'SPB Loss Calculator'!$B$8,m,'SPB Loss Calculator'!$B$9,Rds,'SPB Loss Calculator'!$B$14/1000,Eon,'SPB Loss Calculator'!$B$12,Eoff,'SPB Loss Calculator'!$B$13,Vref,'SPB Loss Calculator'!$B$17,Iref,'SPB Loss Calculator'!$B$18,av,'SPB Loss Calculator'!$B$19,ai,'SPB Loss Calculator'!$B$20,fixed,'SPB Loss Calculator'!$B$21,N,$A12,fsw,B$5,Vmod,Vdc/N,Vll,0.6123724357*m*Vmod,Irms,Pkw*1000/(SQRT(3)*Vll*pf),Pcond,N*3*Irms^2*Rds,Esw,(Eon+Eoff)*(Vmod/Vref)^av*(Irms/Iref)^ai,Psw,6*N*(Esw/1000)*(fsw*1000),Pkw*1000/(Pkw*1000+Pcond+Psw+fixed)*100) -> #NAME? | C12: =_xludf.LET(Vdc,'SPB Loss Calculator'!$B$5,Pkw,'SPB Loss Calculator'!$B$7,pf,'SPB Loss Calculator'!$B$8,m,'SPB Loss Calculator'!$B$9,Rds,'SPB Loss Calculator'!$B$14/1000,Eon,'SPB Loss Calculator'!$B$12,Eoff,'SPB Loss Calculator'!$B$13,Vref,'SPB Loss Calculator'!$B$17,Iref,'SPB Loss Calculator'!$B$18,av,'SPB Loss Calculator'!$B$19,ai,'SPB Loss Calculator'!$B$20,fixed,'SPB Loss Calculator'!$B$21,N,$A12,fsw,C$5,Vmod,Vdc/N,Vll,0.6123724357*m*Vmod,Irms,Pkw*1000/(SQRT(3)*Vll*pf),Pcond,N*3*Irms^2*Rds,Esw,(Eon+Eoff)*(Vmod/Vref)^av*(Irms/Iref)^ai,Psw,6*N*(Esw/1000)*(fsw*1000),Pkw*1000/(Pkw*1000+Pcond+Psw+fixed)*100) -> #NAME? | D12: =_xludf.LET(Vdc,'SPB Loss Calculator'!$B$5,Pkw,'SPB Loss Calculator'!$B$7,pf,'SPB Loss Calculator'!$B$8,m,'SPB Loss Calculator'!$B$9,Rds,'SPB Loss Calculator'!$B$14/1000,Eon,'SPB Loss Calculator'!$B$12,Eoff,'SPB Loss Calculator'!$B$13,Vref,'SPB Loss Calculator'!$B$17,Iref,'SPB Loss Calculator'!$B$18,av,'SPB Loss Calculator'!$B$19,ai,'SPB Loss Calculator'!$B$20,fixed,'SPB Loss Calculator'!$B$21,N,$A12,fsw,D$5,Vmod,Vdc/N,Vll,0.6123724357*m*Vmod,Irms,Pkw*1000/(SQRT(3)*Vll*pf),Pcond,N*3*Irms^2*Rds,Esw,(Eon+Eoff)*(Vmod/Vref)^av*(Irms/Iref)^ai,Psw,6*N*(Esw/1000)*(fsw*1000),Pkw*1000/(Pkw*1000+Pcond+Psw+fixed)*100) -> #NAME? | E12: =_xludf.LET(Vdc,'SPB Loss Calculator'!$B$5,Pkw,'SPB Loss Calculator'!$B$7,pf,'SPB Loss Calculator'!$B$8,m,'SPB Loss Calculator'!$B$9,Rds,'SPB Loss Calculator'!$B$14/1000,Eon,'SPB Loss Calculator'!$B$12,Eoff,'SPB Loss Calculator'!$B$13,Vref,'SPB Loss Calculator'!$B$17,Iref,'SPB Loss Calculator'!$B$18,av,'SPB Loss Calculator'!$B$19,ai,'SPB Loss Calculator'!$B$20,fixed,'SPB Loss Calculator'!$B$21,N,$A12,fsw,E$5,Vmod,Vdc/N,Vll,0.6123724357*m*Vmod,Irms,Pkw*1000/(SQRT(3)*Vll*pf),Pcond,N*3*Irms^2*Rds,Esw,(Eon+Eoff)*(Vmod/Vref)^av*(Irms/Iref)^ai,Psw,6*N*(Esw/1000)*(fsw*1000),Pkw*1000/(Pkw*1000+Pcond+Psw+fixed)*100) -> #NAME? | F12: =_xludf.LET(Vdc,'SPB Loss Calculator'!$B$5,Pkw,'SPB Loss Calculator'!$B$7,pf,'SPB Loss Calculator'!$B$8,m,'SPB Loss Calculator'!$B$9,Rds,'SPB Loss Calculator'!$B$14/1000,Eon,'SPB Loss Calculator'!$B$12,Eoff,'SPB Loss Calculator'!$B$13,Vref,'SPB Loss Calculator'!$B$17,Iref,'SPB Loss Calculator'!$B$18,av,'SPB Loss Calculator'!$B$19,ai,'SPB Loss Calculator'!$B$20,fixed,'SPB Loss Calculator'!$B$21,N,$A12,fsw,F$5,Vmod,Vdc/N,Vll,0.6123724357*m*Vmod,Irms,Pkw*1000/(SQRT(3)*Vll*pf),Pcond,N*3*Irms^2*Rds,Esw,(Eon+Eoff)*(Vmod/Vref)^av*(Irms/Iref)^ai,Psw,6*N*(Esw/1000)*(fsw*1000),Pkw*1000/(Pkw*1000+Pcond+Psw+fixed)*100) -> #NAME? | G12: =_xludf.LET(Vdc,'SPB Loss Calculator'!$B$5,Pkw,'SPB Loss Calculator'!$B$7,pf,'SPB Loss Calculator'!$B$8,m,'SPB Loss Calculator'!$B$9,Rds,'SPB Loss Calculator'!$B$14/1000,Eon,'SPB Loss Calculator'!$B$12,Eoff,'SPB Loss Calculator'!$B$13,Vref,'SPB Loss Calculator'!$B$17,Iref,'SPB Loss Calculator'!$B$18,av,'SPB Loss Calculator'!$B$19,ai,'SPB Loss Calculator'!$B$20,fixed,'SPB Loss Calculator'!$B$21,N,$A12,fsw,G$5,Vmod,Vdc/N,Vll,0.6123724357*m*Vmod,Irms,Pkw*1000/(SQRT(3)*Vll*pf),Pcond,N*3*Irms^2*Rds,Esw,(Eon+Eoff)*(Vmod/Vref)^av*(Irms/Iref)^ai,Psw,6*N*(Esw/1000)*(fsw*1000),Pkw*1000/(Pkw*1000+Pcond+Psw+fixed)*100) -> #NAME? | H12: =_xludf.LET(Vdc,'SPB Loss Calculator'!$B$5,Pkw,'SPB Loss Calculator'!$B$7,pf,'SPB Loss Calculator'!$B$8,m,'SPB Loss Calculator'!$B$9,Rds,'SPB Loss Calculator'!$B$14/1000,Eon,'SPB Loss Calculator'!$B$12,Eoff,'SPB Loss Calculator'!$B$13,Vref,'SPB Loss Calculator'!$B$17,Iref,'SPB Loss Calculator'!$B$18,av,'SPB Loss Calculator'!$B$19,ai,'SPB Loss Calculator'!$B$20,fixed,'SPB Loss Calculator'!$B$21,N,$A12,fsw,H$5,Vmod,Vdc/N,Vll,0.6123724357*m*Vmod,Irms,Pkw*1000/(SQRT(3)*Vll*pf),Pcond,N*3*Irms^2*Rds,Esw,(Eon+Eoff)*(Vmod/Vref)^av*(Irms/Iref)^ai,Psw,6*N*(Esw/1000)*(fsw*1000),Pkw*1000/(Pkw*1000+Pcond+Psw+fixed)*100) -> #NAME?
A13: 8 | B13: =_xludf.LET(Vdc,'SPB Loss Calculator'!$B$5,Pkw,'SPB Loss Calculator'!$B$7,pf,'SPB Loss Calculator'!$B$8,m,'SPB Loss Calculator'!$B$9,Rds,'SPB Loss Calculator'!$B$14/1000,Eon,'SPB Loss Calculator'!$B$12,Eoff,'SPB Loss Calculator'!$B$13,Vref,'SPB Loss Calculator'!$B$17,Iref,'SPB Loss Calculator'!$B$18,av,'SPB Loss Calculator'!$B$19,ai,'SPB Loss Calculator'!$B$20,fixed,'SPB Loss Calculator'!$B$21,N,$A13,fsw,B$5,Vmod,Vdc/N,Vll,0.6123724357*m*Vmod,Irms,Pkw*1000/(SQRT(3)*Vll*pf),Pcond,N*3*Irms^2*Rds,Esw,(Eon+Eoff)*(Vmod/Vref)^av*(Irms/Iref)^ai,Psw,6*N*(Esw/1000)*(fsw*1000),Pkw*1000/(Pkw*1000+Pcond+Psw+fixed)*100) -> #NAME? | C13: =_xludf.LET(Vdc,'SPB Loss Calculator'!$B$5,Pkw,'SPB Loss Calculator'!$B$7,pf,'SPB Loss Calculator'!$B$8,m,'SPB Loss Calculator'!$B$9,Rds,'SPB Loss Calculator'!$B$14/1000,Eon,'SPB Loss Calculator'!$B$12,Eoff,'SPB Loss Calculator'!$B$13,Vref,'SPB Loss Calculator'!$B$17,Iref,'SPB Loss Calculator'!$B$18,av,'SPB Loss Calculator'!$B$19,ai,'SPB Loss Calculator'!$B$20,fixed,'SPB Loss Calculator'!$B$21,N,$A13,fsw,C$5,Vmod,Vdc/N,Vll,0.6123724357*m*Vmod,Irms,Pkw*1000/(SQRT(3)*Vll*pf),Pcond,N*3*Irms^2*Rds,Esw,(Eon+Eoff)*(Vmod/Vref)^av*(Irms/Iref)^ai,Psw,6*N*(Esw/1000)*(fsw*1000),Pkw*1000/(Pkw*1000+Pcond+Psw+fixed)*100) -> #NAME? | D13: =_xludf.LET(Vdc,'SPB Loss Calculator'!$B$5,Pkw,'SPB Loss Calculator'!$B$7,pf,'SPB Loss Calculator'!$B$8,m,'SPB Loss Calculator'!$B$9,Rds,'SPB Loss Calculator'!$B$14/1000,Eon,'SPB Loss Calculator'!$B$12,Eoff,'SPB Loss Calculator'!$B$13,Vref,'SPB Loss Calculator'!$B$17,Iref,'SPB Loss Calculator'!$B$18,av,'SPB Loss Calculator'!$B$19,ai,'SPB Loss Calculator'!$B$20,fixed,'SPB Loss Calculator'!$B$21,N,$A13,fsw,D$5,Vmod,Vdc/N,Vll,0.6123724357*m*Vmod,Irms,Pkw*1000/(SQRT(3)*Vll*pf),Pcond,N*3*Irms^2*Rds,Esw,(Eon+Eoff)*(Vmod/Vref)^av*(Irms/Iref)^ai,Psw,6*N*(Esw/1000)*(fsw*1000),Pkw*1000/(Pkw*1000+Pcond+Psw+fixed)*100) -> #NAME? | E13: =_xludf.LET(Vdc,'SPB Loss Calculator'!$B$5,Pkw,'SPB Loss Calculator'!$B$7,pf,'SPB Loss Calculator'!$B$8,m,'SPB Loss Calculator'!$B$9,Rds,'SPB Loss Calculator'!$B$14/1000,Eon,'SPB Loss Calculator'!$B$12,Eoff,'SPB Loss Calculator'!$B$13,Vref,'SPB Loss Calculator'!$B$17,Iref,'SPB Loss Calculator'!$B$18,av,'SPB Loss Calculator'!$B$19,ai,'SPB Loss Calculator'!$B$20,fixed,'SPB Loss Calculator'!$B$21,N,$A13,fsw,E$5,Vmod,Vdc/N,Vll,0.6123724357*m*Vmod,Irms,Pkw*1000/(SQRT(3)*Vll*pf),Pcond,N*3*Irms^2*Rds,Esw,(Eon+Eoff)*(Vmod/Vref)^av*(Irms/Iref)^ai,Psw,6*N*(Esw/1000)*(fsw*1000),Pkw*1000/(Pkw*1000+Pcond+Psw+fixed)*100) -> #NAME? | F13: =_xludf.LET(Vdc,'SPB Loss Calculator'!$B$5,Pkw,'SPB Loss Calculator'!$B$7,pf,'SPB Loss Calculator'!$B$8,m,'SPB Loss Calculator'!$B$9,Rds,'SPB Loss Calculator'!$B$14/1000,Eon,'SPB Loss Calculator'!$B$12,Eoff,'SPB Loss Calculator'!$B$13,Vref,'SPB Loss Calculator'!$B$17,Iref,'SPB Loss Calculator'!$B$18,av,'SPB Loss Calculator'!$B$19,ai,'SPB Loss Calculator'!$B$20,fixed,'SPB Loss Calculator'!$B$21,N,$A13,fsw,F$5,Vmod,Vdc/N,Vll,0.6123724357*m*Vmod,Irms,Pkw*1000/(SQRT(3)*Vll*pf),Pcond,N*3*Irms^2*Rds,Esw,(Eon+Eoff)*(Vmod/Vref)^av*(Irms/Iref)^ai,Psw,6*N*(Esw/1000)*(fsw*1000),Pkw*1000/(Pkw*1000+Pcond+Psw+fixed)*100) -> #NAME? | G13: =_xludf.LET(Vdc,'SPB Loss Calculator'!$B$5,Pkw,'SPB Loss Calculator'!$B$7,pf,'SPB Loss Calculator'!$B$8,m,'SPB Loss Calculator'!$B$9,Rds,'SPB Loss Calculator'!$B$14/1000,Eon,'SPB Loss Calculator'!$B$12,Eoff,'SPB Loss Calculator'!$B$13,Vref,'SPB Loss Calculator'!$B$17,Iref,'SPB Loss Calculator'!$B$18,av,'SPB Loss Calculator'!$B$19,ai,'SPB Loss Calculator'!$B$20,fixed,'SPB Loss Calculator'!$B$21,N,$A13,fsw,G$5,Vmod,Vdc/N,Vll,0.6123724357*m*Vmod,Irms,Pkw*1000/(SQRT(3)*Vll*pf),Pcond,N*3*Irms^2*Rds,Esw,(Eon+Eoff)*(Vmod/Vref)^av*(Irms/Iref)^ai,Psw,6*N*(Esw/1000)*(fsw*1000),Pkw*1000/(Pkw*1000+Pcond+Psw+fixed)*100) -> #NAME? | H13: =_xludf.LET(Vdc,'SPB Loss Calculator'!$B$5,Pkw,'SPB Loss Calculator'!$B$7,pf,'SPB Loss Calculator'!$B$8,m,'SPB Loss Calculator'!$B$9,Rds,'SPB Loss Calculator'!$B$14/1000,Eon,'SPB Loss Calculator'!$B$12,Eoff,'SPB Loss Calculator'!$B$13,Vref,'SPB Loss Calculator'!$B$17,Iref,'SPB Loss Calculator'!$B$18,av,'SPB Loss Calculator'!$B$19,ai,'SPB Loss Calculator'!$B$20,fixed,'SPB Loss Calculator'!$B$21,N,$A13,fsw,H$5,Vmod,Vdc/N,Vll,0.6123724357*m*Vmod,Irms,Pkw*1000/(SQRT(3)*Vll*pf),Pcond,N*3*Irms^2*Rds,Esw,(Eon+Eoff)*(Vmod/Vref)^av*(Irms/Iref)^ai,Psw,6*N*(Esw/1000)*(fsw*1000),Pkw*1000/(Pkw*1000+Pcond+Psw+fixed)*100) -> #NAME?

Sheet Assumptions & Notes
A1: Assumptions and formula notes
A2: 1. The workbook is a first-order loss estimator, not a substitute for datasheet- and waveform-based detailed loss simulation.
A3: 2. SPB module voltage is calculated as total DC-link voltage divided by the number of series SPB modules.
A4: 3. Fundamental module line-line RMS voltage is approximated as 0.612·m·Vdc,module for a two-level three-phase bridge.
A5: 4. Phase current is estimated from Pmodule = √3·VLL,rms,module·Iphase,rms·power factor.
A6: 5. Conduction loss is approximated as N·3·Irms²·Rds(on), assuming MOSFET conduction and sinusoidal current.
A7: 6. Switching loss is approximated as 6·N·(Eon+Eoff scaled)·fsw. Eon/Eoff are per switch and entered in mJ.
A8: 7. Switching energy scaling uses (Vmodule/Vref)^aV·(Irms/Iref)^aI. Keep both exponents at 1 for linear scaling.
A9: 8. The calculator ignores diode reverse recovery, dead-time conduction, temperature dependence of Rds(on), gate-drive losses unless entered as fixed losses, capacitor losses, machine losses, and thermal derating.
A10: 9. Literature context: SPB is based on dc-side cascading of conventional two-level three-phase inverter bridges, enabling low-voltage devices and modularity; the uploaded literature survey contains notes on this SPB concept and loss-analysis papers.
A11: 10. Source note: user-provided literature survey PowerPoint: /mnt/data/immd_literature2020.pptx
